Workbook

Sheet Cover
B7: Cover Page | C7: Page
B8: Assumptions | C8: =Assumptions!A1 -> 0
B9: Calcs | C9: =Calcs!A1 -> 0
B10: Income Statement | C10: ='Income Statement'!A1 -> 0
B11: Balance Sheet | C11: ='Balance Sheet'!A1 -> 0
B12: Cash Flow Statement | C12: ='Cash Flow Statement'!A1 -> 0
B13: Debt Schedule | C13: ='Debt Schedule'!A1 -> 0
B14: LTM | C14: =LTMS!A3 -> 0
B15: Comps | C15: =Comps!A1 -> 0
B16: WACC | C16: =WACC!A1 -> 0
B17: DCF | C17: =DCF!A1 -> 0

Sheet Assumptions
B2: Assumptions | C2: Historical | I2: Average % | L2: Projected | S2: Projected | Z2: Projected | AG2: Projected
C3: 2021 | D3: =C3+1 -> 2022 | E3: =D3+1 -> 2023 | F3: =E3+1 -> 2024 | G3: =F3+1 -> 2025 | I3: 3YR AVG | J3: 5YR AVG | L3: =G3+1 -> 2026 | M3: =L3+1 -> 2027 | N3: =M3+1 -> 2028 | O3: =N3+1 -> 2029 | P3: =O3+1 -> 2030 | T3: 2026 | U3: 2027 | V3: 2028 | W3: 2029 | X3: 2030 | AA3: 2026 | AB3: 2027 | AC3: 2028 | AD3: 2029 | AE3: 2030 | AH3: 2026 | AI3: 2027 | AJ3: 2028 | AK3: 2029 | AL3: 2030
B4: Income Statement | N4: Base | S4: Bull | Z4: Bear | AG4: Base
A5: x | B5: Products ( Pharmacy Revenues) (ASC 606) | AO5: Bull
B6: Network Revenues | D6: =('Income Statement'!D6-'Income Statement'!C6)/'Income Statement'!C6 -> -0.00070777942 | E6: =('Income Statement'!E6-'Income Statement'!D6)/'Income Statement'!D6 -> 0.039540541 | F6: =('Income Statement'!F6-'Income Statement'!E6)/'Income Statement'!E6 -> 0.56026898 | G6: =('Income Statement'!G6-'Income Statement'!F6)/'Income Statement'!F6 -> 0.19207329 | I6: =AVERAGE(E6:G6) -> 0.26396094 | J6: =AVERAGE(D6:G6) -> 0.19779376 | L6: {=_xlfn.IFS($N$4="Bull",T6, $N$4="Bear",AA6, $N$4="Base",AH6)} -> 0.14 | M6: {=_xlfn.IFS($N$4="Bull",U6, $N$4="Bear",AB6, $N$4="Base",AI6)} -> 0.12 | N6: {=_xlfn.IFS($N$4="Bull",V6, $N$4="Bear",AC6, $N$4="Base",AJ6)} -> 0.08 | O6: {=_xlfn.IFS($N$4="Bull",W6, $N$4="Bear",AD6, $N$4="Base",AK6)} -> 0.065 | P6: {=_xlfn.IFS($N$4="Bull",X6, $N$4="Bear",AE6, $N$4="Base",AL6)} -> 0.065 | T6: 0.2 | U6: 0.17 | V6: 0.185 | W6: 0.19 | X6: 0.205 | AA6: 0.1 | AB6: 0.075 | AC6: 0.05 | AD6: 0.035 | AE6: 0.035 | AH6: 0.14 | AI6: 0.12 | AJ6: 0.08 | AK6: 0.065 | AL6: 0.065 | AO6: Bear
B7: Home Delivery and Specialty | D7: =('Income Statement'!D7-'Income Statement'!C7)/'Income Statement'!C7 -> 0.12671214 | E7: =('Income Statement'!E7-'Income Statement'!D7)/'Income Statement'!D7 -> 0.072597621 | F7: =('Income Statement'!F7-'Income Statement'!E7)/'Income Statement'!E7 -> 0.10259843 | G7: =('Income Statement'!G7-'Income Statement'!F7)/'Income Statement'!F7 -> 0.11060213 | I7: =AVERAGE(E7:G7) -> 0.09526606 | J7: =AVERAGE(D7:G7) -> 0.10312758 | L7: {=_xlfn.IFS($N$4="Bull",T7, $N$4="Bear",AA7, $N$4="Base",AH7)} -> 0.113 | M7: {=_xlfn.IFS($N$4="Bull",U7, $N$4="Bear",AB7, $N$4="Base",AI7)} -> 0.1 | N7: {=_xlfn.IFS($N$4="Bull",V7, $N$4="Bear",AC7, $N$4="Base",AJ7)} -> 0.095 | O7: {=_xlfn.IFS($N$4="Bull",W7, $N$4="Bear",AD7, $N$4="Base",AK7)} -> 0.08 | P7: {=_xlfn.IFS($N$4="Bull",X7, $N$4="Bear",AE7, $N$4="Base",AL7)} -> 0.08 | T7: 0.115 | U7: 0.11 | V7: 0.105 | W7: 0.1 | X7: 0.095 | AA7: 0.08 | AB7: 0.07 | AC7: 0.06 | AD7: 0.05 | AE7: 0.05 | AH7: 0.113 | AI7: 0.1 | AJ7: 0.095 | AK7: 0.08 | AL7: 0.08 | AO7: Base
B8: Other Revenues | D8: =('Income Statement'!D8-'Income Statement'!C8)/'Income Statement'!C8 -> 0.05056005 | E8: =('Income Statement'!E8-'Income Statement'!D8)/'Income Statement'!D8 -> 0.33970087 | F8: =('Income Statement'!F8-'Income Statement'!E8)/'Income Statement'!E8 -> 0.27611363 | G8: =('Income Statement'!G8-'Income Statement'!F8)/'Income Statement'!F8 -> 0.15452577 | I8: =AVERAGE(E8:G8) -> 0.25678009 | J8: =AVERAGE(D8:G8) -> 0.20522508 | L8: {=_xlfn.IFS($N$4="Bull",T8, $N$4="Bear",AA8, $N$4="Base",AH8)} -> 0.1395 | M8: {=_xlfn.IFS($N$4="Bull",U8, $N$4="Bear",AB8, $N$4="Base",AI8)} -> 0.118 | N8: {=_xlfn.IFS($N$4="Bull",V8, $N$4="Bear",AC8, $N$4="Base",AJ8)} -> 0.11 | O8: {=_xlfn.IFS($N$4="Bull",W8, $N$4="Bear",AD8, $N$4="Base",AK8)} -> 0.105 | P8: {=_xlfn.IFS($N$4="Bull",X8, $N$4="Bear",AE8, $N$4="Base",AL8)} -> 0.105 | T8: 0.16 | U8: 0.14 | V8: 0.13 | W8: 0.11 | X8: 0.108 | AA8: 0.09 | AB8: 0.075 | AC8: 0.065 | AD8: 0.06 | AE8: 0.06 | AH8: 0.1395 | AI8: 0.118 | AJ8: 0.11 | AK8: 0.105 | AL8: 0.105
B9: Other Operations | G9: =('Income Statement'!G9-'Income Statement'!F9)/'Income Statement'!F9 -> -0.1 | I9: =AVERAGE(E9:G9) -> -0.1 | J9: =AVERAGE(D9:G9) -> -0.1 | L9: {=_xlfn.IFS($N$4="Bull",T9, $N$4="Bear",AA9, $N$4="Base",AH9)} -> -0.1 | M9: {=_xlfn.IFS($N$4="Bull",U9, $N$4="Bear",AB9, $N$4="Base",AI9)} -> -0.1 | N9: {=_xlfn.IFS($N$4="Bull",V9, $N$4="Bear",AC9, $N$4="Base",AJ9)} -> -0.1 | O9: {=_xlfn.IFS($N$4="Bull",W9, $N$4="Bear",AD9, $N$4="Base",AK9)} -> -0.1 | P9: {=_xlfn.IFS($N$4="Bull",X9, $N$4="Bear",AE9, $N$4="Base",AL9)} -> -0.1 | T9: -0.1 | U9: -0.1 | V9: -0.1 | W9: -0.1 | X9: -0.1 | AA9: -0.1 | AB9: -0.1 | AC9: -0.1 | AD9: -0.1 | AE9: -0.1 | AH9: -0.1 | AI9: -0.1 | AJ9: -0.1 | AK9: -0.1 | AL9: -0.1
B10: Intercompany Eliminations | D10: =('Income Statement'!D10-'Income Statement'!C10)/'Income Statement'!C10 -> 0.0040927694 | E10: =('Income Statement'!E10-'Income Statement'!D10)/'Income Statement'!D10 -> 0.14356884 | F10: =('Income Statement'!F10-'Income Statement'!E10)/'Income Statement'!E10 -> -0.19623762 | G10: =('Income Statement'!G10-'Income Statement'!F10)/'Income Statement'!F10 -> -0.31608771 | I10: =AVERAGE(E10:G10) -> -0.12291883 | J10: =AVERAGE(D10:G10) -> -0.09116593 | L10: {=_xlfn.IFS($N$4="Bull",T10, $N$4="Bear",AA10, $N$4="Base",AH10)} -> -0.245 | M10: {=_xlfn.IFS($N$4="Bull",U10, $N$4="Bear",AB10, $N$4="Base",AI10)} -> -0.205 | N10: {=_xlfn.IFS($N$4="Bull",V10, $N$4="Bear",AC10, $N$4="Base",AJ10)} -> -0.172 | O10: {=_xlfn.IFS($N$4="Bull",W10, $N$4="Bear",AD10, $N$4="Base",AK10)} -> -0.12 | P10: {=_xlfn.IFS($N$4="Bull",X10, $N$4="Bear",AE10, $N$4="Base",AL10)} -> -0.12 | T10: -0.22 | U10: -0.19 | V10: -0.15 | W10: -0.1 | X10: -0.11 | AA10: -0.32 | AB10: -0.27 | AC10: -0.23 | AD10: -0.18 | AE10: -0.18 | AH10: -0.245 | AI10: -0.205 | AJ10: -0.172 | AK10: -0.12 | AL10: -0.12
B12: Insurance Premiums (ASC 944)
B13: Cigna Healthcare
A14: x | B14: U.S Commercial
B15: Insured | D15: =('Income Statement'!D15-'Income Statement'!C15)/'Income Statement'!C15 -> 0.061753406 | E15: =('Income Statement'!E15-'Income Statement'!D15)/'Income Statement'!D15 -> 0.084939799 | F15: =('Income Statement'!F15-'Income Statement'!E15)/'Income Statement'!E15 -> 0.065858096 | G15: =('Income Statement'!G15-'Income Statement'!F15)/'Income Statement'!F15 -> 0.072598999 | I15: =AVERAGE(E15:G15) -> 0.074465631 | J15: =AVERAGE(D15:G15) -> 0.071287575 | L15: {=_xlfn.IFS($N$4="Bull",T15, $N$4="Bear",AA15, $N$4="Base",AH15)} -> 0.03 | M15: {=_xlfn.IFS($N$4="Bull",U15, $N$4="Bear",AB15, $N$4="Base",AI15)} -> 0.034 | N15: {=_xlfn.IFS($N$4="Bull",V15, $N$4="Bear",AC15, $N$4="Base",AJ15)} -> 0.034 | O15: {=_xlfn.IFS($N$4="Bull",W15, $N$4="Bear",AD15, $N$4="Base",AK15)} -> 0.05 | P15: {=_xlfn.IFS($N$4="Bull",X15, $N$4="Bear",AE15, $N$4="Base",AL15)} -> 0.05 | T15: 0.08 | U15: 0.0775 | V15: 0.075 | W15: 0.0725 | X15: 0.07 | AA15: 0.055 | AB15: 0.05 | AC15: 0.045 | AD15: 0.04 | AE15: 0.04 | AH15: 0.03 | AI15: 0.034 | AJ15: 0.034 | AK15: 0.05 | AL15: 0.05
B16: Stop Loss | D16: =('Income Statement'!D16-'Income Statement'!C16)/'Income Statement'!C16 -> 0.12181594 | E16: =('Income Statement'!E16-'Income Statement'!D16)/'Income Statement'!D16 -> 0.12488555 | F16: =('Income Statement'!F16-'Income Statement'!E16)/'Income Statement'!E16 -> 0.097834934 | G16: =('Income Statement'!G16-'Income Statement'!F16)/'Income Statement'!F16 -> 0.12677936 | I16: =AVERAGE(E16:G16) -> 0.11649995 | J16: =AVERAGE(F16:H16) -> 0.11230715 | L16: {=_xlfn.IFS($N$4="Bull",T16, $N$4="Bear",AA16, $N$4="Base",AH16)} -> 0.125 | M16: {=_xlfn.IFS($N$4="Bull",U16, $N$4="Bear",AB16, $N$4="Base",AI16)} -> 0.115 | N16: {=_xlfn.IFS($N$4="Bull",V16, $N$4="Bear",AC16, $N$4="Base",AJ16)} -> 0.11 | O16: {=_xlfn.IFS($N$4="Bull",W16, $N$4="Bear",AD16, $N$4="Base",AK16)} -> 0.105 | P16: {=_xlfn.IFS($N$4="Bull",X16, $N$4="Bear",AE16, $N$4="Base",AL16)} -> 0.105 | T16: 0.125 | U16: 0.1275 | V16: 0.13 | W16: 0.1325 | X16: 0.135 | AA16: 0.09 | AB16: 0.08 | AC16: 0.07 | AD16: 0.065 | AE16: 0.065 | AH16: 0.125 | AI16: 0.115 | AJ16: 0.11 | AK16: 0.105 | AL16: 0.105
B17: Other | D17: =('Income Statement'!D17-'Income Statement'!C17)/'Income Statement'!C17 -> 0.099224806 | E17: =('Income Statement'!E17-'Income Statement'!D17)/'Income Statement'!D17 -> 2.5881523 | F17: =('Income Statement'!F17-'Income Statement'!E17)/'Income Statement'!E17 -> -0.22346698 | G17: =('Income Statement'!G17-'Income Statement'!F17)/'Income Statement'!F17 -> -0.14679828 | I17: =AVERAGE(E17:G17) -> 0.73929569 | J17: =AVERAGE(F17:H17) -> -0.18513263 | L17: {=_xlfn.IFS($N$4="Bull",T17, $N$4="Bear",AA17, $N$4="Base",AH17)} -> -0.15 | M17: {=_xlfn.IFS($N$4="Bull",U17, $N$4="Bear",AB17, $N$4="Base",AI17)} -> -0.1 | N17: {=_xlfn.IFS($N$4="Bull",V17, $N$4="Bear",AC17, $N$4="Base",AJ17)} -> -0.08 | O17: {=_xlfn.IFS($N$4="Bull",W17, $N$4="Bear",AD17, $N$4="Base",AK17)} -> -0.05 | P17: {=_xlfn.IFS($N$4="Bull",X17, $N$4="Bear",AE17, $N$4="Base",AL17)} -> -0.05 | T17: 0.2771 | U17: 0.2771 | V17: 0.2771 | W17: 0.2771 | X17: 0.2771 | AA17: -0.2 | AB17: -0.15 | AC17: -0.12 | AD17: -0.08 | AE17: -0.08 | AH17: -0.15 | AI17: -0.1 | AJ17: -0.08 | AK17: -0.05 | AL17: -0.05
A19: x | B19: U.S Government
B20: Medicare Advantage | D20: =('Income Statement'!D19-'Income Statement'!C19)/'Income Statement'!C19 -> -0.055728295 | E20: =('Income Statement'!E19-'Income Statement'!D19)/'Income Statement'!D19 -> 0.1108156 | F20: =('Income Statement'!F19-'Income Statement'!E19)/'Income Statement'!E19 -> -0.010489112 | G20: =('Income Statement'!G19-'Income Statement'!F19)/'Income Statement'!F19 -> -0.72773361 | I20: =AVERAGE(E20:G20) -> -0.20913571 | J20: =AVERAGE(D20:G20) -> -0.17078385 | L20: {=_xlfn.IFS($N$4="Bull",AA20, $N$4="Bear",T20, $N$4="Base",AH20)} -> -0.3 | M20: {=_xlfn.IFS($N$4="Bull",AB20, $N$4="Bear",U20, $N$4="Base",AI20)} -> -0.5 | N20: {=_xlfn.IFS($N$4="Bull",AC20, $N$4="Bear",V20, $N$4="Base",AJ20)} -> -1 | O20: {=_xlfn.IFS($N$4="Bull",AD20, $N$4="Bear",W20, $N$4="Base",AK20)} -> 0 | P20: {=_xlfn.IFS($N$4="Bull",AE20, $N$4="Bear",X20, $N$4="Base",AL20)} -> 0 | T20: -0.2 | U20: -0.4 | V20: -0.6 | W20: -0.8 | X20: -1 | AA20: -0.5 | AB20: -0.75 | AC20: -1 | AD20: 0 | AE20: 0 | AH20: -0.3 | AI20: -0.5 | AJ20: -1 | AK20: 0 | AL20: 0
B21: Medicare Part D | D21: =('Income Statement'!D20-'Income Statement'!C20)/'Income Statement'!C19 -> -0.032886869 | E21: =('Income Statement'!E20-'Income Statement'!D20)/'Income Statement'!D19 -> -0.1550152 | F21: =('Income Statement'!F20-'Income Statement'!E20)/'Income Statement'!E19 -> 0 | G21: =('Income Statement'!G20-'Income Statement'!F20)/'Income Statement'!F19 -> 0 | I21: =AVERAGE(E21:G21) -> -0.051671733 | J21: =AVERAGE(D21:G21) -> -0.046975517 | L21: {=_xlfn.IFS($N$4="Bull",AA21, $N$4="Bear",T21, $N$4="Base",AH21)} -> 0.02 | M21: {=_xlfn.IFS($N$4="Bull",AB21, $N$4="Bear",U21, $N$4="Base",AI21)} -> 0.02 | N21: {=_xlfn.IFS($N$4="Bull",AC21, $N$4="Bear",V21, $N$4="Base",AJ21)} -> 0.02 | O21: {=_xlfn.IFS($N$4="Bull",AD21, $N$4="Bear",W21, $N$4="Base",AK21)} -> 0.02 | P21: {=_xlfn.IFS($N$4="Bull",AE21, $N$4="Bear",X21, $N$4="Base",AL21)} -> 0.02 | T21: 0.02 | U21: 0.03 | V21: 0 | W21: 0.01 | X21: 0 | AA21: 0 | AB21: 0.01 | AC21: -0.04 | AD21: -0.06 | AE21: -0.04 | AH21: 0.02 | AI21: 0.02 | AJ21: 0.02 | AK21: 0.02 | AL21: 0.02
B22: Other | D22: =('Income Statement'!D21-'Income Statement'!C21)/'Income Statement'!C21 -> -0.17133956 | E22: =('Income Statement'!E21-'Income Statement'!D21)/'Income Statement'!D21 -> 0.026315789 | F22: =('Income Statement'!F21-'Income Statement'!E21)/'Income Statement'!E21 -> 0.20586081 | G22: =('Income Statement'!G21-'Income Statement'!F21)/'Income Statement'!F21 -> -0.31834751 | I22: =AVERAGE(E22:G22) -> -0.028723638 | J22: =AVERAGE(D22:G22) -> -0.064377619 | L22: {=_xlfn.IFS($N$4="Bull",T22, $N$4="Bear",AA22, $N$4="Base",AH22)} -> 0.01 | M22: {=_xlfn.IFS($N$4="Bull",U22, $N$4="Bear",AB22, $N$4="Base",AI22)} -> 0.01 | N22: {=_xlfn.IFS($N$4="Bull",V22, $N$4="Bear",AC22, $N$4="Base",AJ22)} -> 0.02 | O22: {=_xlfn.IFS($N$4="Bull",W22, $N$4="Bear",AD22, $N$4="Base",AK22)} -> 0.02 | P22: {=_xlfn.IFS($N$4="Bull",X22, $N$4="Bear",AE22, $N$4="Base",AL22)} -> 0.01 | T22: 0.03 | U22: 0.03 | V22: 0.03 | W22: 0.03 | X22: 0.03 | AA22: 0.01 | AB22: 0.01 | AC22: 0.01 | AD22: 0.01 | AE22: 0.01 | AH22: 0.01 | AI22: 0.01 | AJ22: 0.02 | AK22: 0.02 | AL22: 0.01
B23: International Health | D23: =('Income Statement'!D22-'Income Statement'!C22)/'Income Statement'!C22 -> 0.12287481 | E23: =('Income Statement'!E22-'Income Statement'!D22)/'Income Statement'!D22 -> 0.13386098 | F23: =('Income Statement'!F22-'Income Statement'!E22)/'Income Statement'!E22 -> 0.099848255 | G23: =('Income Statement'!G22-'Income Statement'!F22)/'Income Statement'!F22 -> 0.13852097 | I23: =AVERAGE(E23:G23) -> 0.12407673 | J23: =AVERAGE(D23:G23) -> 0.12377625 | L23: {=_xlfn.IFS($N$4="Bull",T23, $N$4="Bear",AA23, $N$4="Base",AH23)} -> 0.08 | M23: {=_xlfn.IFS($N$4="Bull",U23, $N$4="Bear",AB23, $N$4="Base",AI23)} -> 0.08 | N23: {=_xlfn.IFS($N$4="Bull",V23, $N$4="Bear",AC23, $N$4="Base",AJ23)} -> 0.08 | O23: {=_xlfn.IFS($N$4="Bull",W23, $N$4="Bear",AD23, $N$4="Base",AK23)} -> 0.07 | P23: {=_xlfn.IFS($N$4="Bull",X23, $N$4="Bear",AE23, $N$4="Base",AL23)} -> 0.07 | T23: 0.12 | U23: 0.11 | V23: 0.105 | W23: 0.1 | X23: 0.09 | AA23: 0.08 | AB23: 0.075 | AC23: 0.07 | AD23: 0.065 | AE23: 0.06 | AH23: 0.08 | AI23: 0.08 | AJ23: 0.08 | AK23: 0.07 | AL23: 0.07
B24: Divested International Businesses | D24: =('Income Statement'!D24-'Income Statement'!C24)/'Income Statement'!C24 -> -0.50202808 | E24: =('Income Statement'!E24-'Income Statement'!D24)/'Income Statement'!D24 -> -1 | F24: 0 | G24: 0 | I24: =AVERAGE(E24:G24) -> -0.33333333 | J24: =AVERAGE(D24:G24) -> -0.37550702 | L24: {=_xlfn.IFS($N$4="Bull",T24, $N$4="Bear",AA24, $N$4="Base",AH24)} -> 0 | M24: {=_xlfn.IFS($N$4="Bull",U24, $N$4="Bear",AB24, $N$4="Base",AI24)} -> 0 | N24: {=_xlfn.IFS($N$4="Bull",V24, $N$4="Bear",AC24, $N$4="Base",AJ24)} -> 0 | O24: {=_xlfn.IFS($N$4="Bull",W24, $N$4="Bear",AD24, $N$4="Base",AK24)} -> 0 | P24: {=_xlfn.IFS($N$4="Bull",X24, $N$4="Bear",AE24, $N$4="Base",AL24)} -> 0 | T24: 0 | U24: 0 | V24: 0 | W24: 0 | X24: 0 | AA24: 0 | AB24: 0 | AC24: 0 | AD24: 0 | AE24: 0 | AH24: 0 | AI24: 0 | AJ24: 0 | AK24: 0 | AL24: 0
B25: Domestic Disability; Life and accident | D25: ='Income Statement'!C25 -> 0 | E25: ='Income Statement'!D25 -> 0 | F25: ='Income Statement'!E25 -> 0 | G25: ='Income Statement'!F25 -> 0 | I25: =AVERAGE(E25:G25) -> 0 | J25: =AVERAGE(D25:G25) -> 0 | L25: {=_xlfn.IFS($N$4="Bull",T25, $N$4="Bear",AA25, $N$4="Base",AH25)} -> 0 | M25: {=_xlfn.IFS($N$4="Bull",U25, $N$4="Bear",AB25, $N$4="Base",AI25)} -> 0 | N25: {=_xlfn.IFS($N$4="Bull",V25, $N$4="Bear",AC25, $N$4="Base",AJ25)} -> 0 | O25: {=_xlfn.IFS($N$4="Bull",W25, $N$4="Bear",AD25, $N$4="Base",AK25)} -> 0 | P25: {=_xlfn.IFS($N$4="Bull",X25, $N$4="Bear",AE25, $N$4="Base",AL25)} -> 0 | T25: 0 | U25: 0 | V25: 0 | W25: 0 | X25: 0 | AA25: 0 | AB25: 0 | AC25: 0 | AD25: 0 | AE25: 0 | AH25: 0 | AI25: 0 | AJ25: 0 | AK25: 0 | AL25: 0
B26: Other | D26: =('Income Statement'!D26-'Income Statement'!C26)/'Income Statement'!C26 -> 0.013574661 | E26: =('Income Statement'!E26-'Income Statement'!D26)/'Income Statement'!D26 -> 0.25446429 | F26: =('Income Statement'!F26-'Income Statement'!E26)/'Income Statement'!E26 -> 0.35231317 | G26: =('Income Statement'!G26-'Income Statement'!F26)/'Income Statement'!F26 -> -0.24210526 | I26: =AVERAGE(E26:G26) -> 0.1215574 | J26: =AVERAGE(D26:G26) -> 0.094561713 | L26: {=_xlfn.IFS($N$4="Bull",T26, $N$4="Bear",AA26, $N$4="Base",AH26)} -> 0.10805955 | M26: {=_xlfn.IFS($N$4="Bull",U26, $N$4="Bear",AB26, $N$4="Base",AI26)} -> 0.10805955 | N26: {=_xlfn.IFS($N$4="Bull",V26, $N$4="Bear",AC26, $N$4="Base",AJ26)} -> 0.10805955 | O26: {=_xlfn.IFS($N$4="Bull",W26, $N$4="Bear",AD26, $N$4="Base",AK26)} -> 0.10805955 | P26: {=_xlfn.IFS($N$4="Bull",X26, $N$4="Bear",AE26, $N$4="Base",AL26)} -> 0.10805955 | T26: =AVERAGEA($I$26:$J$26) -> 0.10805955 | U26: =AVERAGEA($I$26:$J$26) -> 0.10805955 | V26: =AVERAGEA($I$26:$J$26) -> 0.10805955 | W26: =AVERAGEA($I$26:$J$26) -> 0.10805955 | X26: =AVERAGEA($I$26:$J$26) -> 0.10805955 | AA26: =AVERAGE($I$26:$J$26) -> 0.10805955 | AB26: =AVERAGE($I$26:$J$26) -> 0.10805955 | AC26: =AVERAGE($I$26:$J$26) -> 0.10805955 | AD26: =AVERAGE($I$26:$J$26) -> 0.10805955 | AE26: =AVERAGE($I$26:$J$26) -> 0.10805955 | AH26: =AVERAGE($I$26:$J$26) -> 0.10805955 | AI26: =AVERAGE($I$26:$J$26) -> 0.10805955 | AJ26: =AVERAGE($I$26:$J$26) -> 0.10805955 | AK26: =AVERAGE($I$26:$J$26) -> 0.10805955 | AL26: =AVERAGE($I$26:$J$26) -> 0.10805955
B27: Intercompany Eliminatioons | D27: =('Income Statement'!D27-'Income Statement'!C27)/'Income Statement'!C27 -> -1.1111111 | E27: =('Income Statement'!E27-'Income Statement'!D27)/'Income Statement'!D27 -> 73 | F27: =('Income Statement'!F27-'Income Statement'!E27)/'Income Statement'!E27 -> 0.40540541 | G27: =('Income Statement'!G27-'Income Statement'!F27)/'Income Statement'!F27 -> 1.8461538 | I27: =AVERAGE(E27:G27) -> 25.083853 | J27: =AVERAGE(D27:G27) -> 18.535112 | L27: {=_xlfn.IFS($N$4="Bull",T27, $N$4="Bear",AA27, $N$4="Base",AH27)} -> 0 | M27: {=_xlfn.IFS($N$4="Bull",U27, $N$4="Bear",AB27, $N$4="Base",AI27)} -> 0 | N27: {=_xlfn.IFS($N$4="Bull",V27, $N$4="Bear",AC27, $N$4="Base",AJ27)} -> 0 | O27: {=_xlfn.IFS($N$4="Bull",W27, $N$4="Bear",AD27, $N$4="Base",AK27)} -> 0 | P27: {=_xlfn.IFS($N$4="Bull",X27, $N$4="Bear",AE27, $N$4="Base",AL27)} -> 0 | T27: 0.01 | U27: 0.01 | V27: 0.01 | W27: 0.01 | X27: 0.01 | AA27: -0.01 | AB27: -0.01 | AC27: -0.01 | AD27: -0.01 | AE27: -0.01 | AH27: 0 | AI27: 0 | AJ27: 0 | AK27: 0 | AL27: 0
A29: x | B29: Service (Fees)(ASC 606)
B30: Evernorth Health Services | D30: =('Income Statement'!D30-'Income Statement'!C30)/'Income Statement'!C30 -> 0.19176277 | E30: =('Income Statement'!E30-'Income Statement'!D30)/'Income Statement'!D30 -> 0.51575892 | F30: =('Income Statement'!F30-'Income Statement'!E30)/'Income Statement'!E30 -> 0.14829001 | G30: =('Income Statement'!G30-'Income Statement'!F30)/'Income Statement'!F30 -> 0.22444603 | I30: =AVERAGE(E30:G30) -> 0.29616499 | J30: =AVERAGE(D30:G30) -> 0.27006443 | L30: {=_xlfn.IFS($N$4="Bull",T30, $N$4="Bear",AA30, $N$4="Base",AH30)} -> 0.2 | M30: {=_xlfn.IFS($N$4="Bull",U30, $N$4="Bear",AB30, $N$4="Base",AI30)} -> 0.205 | N30: {=_xlfn.IFS($N$4="Bull",V30, $N$4="Bear",AC30, $N$4="Base",AJ30)} -> 0.21 | O30: {=_xlfn.IFS($N$4="Bull",W30, $N$4="Bear",AD30, $N$4="Base",AK30)} -> 0.215 | P30: {=_xlfn.IFS($N$4="Bull",X30, $N$4="Bear",AE30, $N$4="Base",AL30)} -> 0.22 | T30: 0.26 | U30: 0.27 | V30: 0.28 | W30: 0.29 | X30: 0.3 | AA30: 0.15 | AB30: 0.17 | AC30: 0.15 | AD30: 0.11 | AE30: 0.09 | AH30: 0.2 | AI30: 0.205 | AJ30: 0.21 | AK30: 0.215 | AL30: 0.22
B31: Cigna Healthcare | D31: =('Income Statement'!D31-'Income Statement'!C31)/'Income Statement'!C31 -> 0.053978757 | E31: =('Income Statement'!E31-'Income Statement'!D31)/'Income Statement'!D31 -> 0.10176772 | F31: =('Income Statement'!F31-'Income Statement'!E31)/'Income Statement'!E31 -> 0.047833258 | G31: =('Income Statement'!G31-'Income Statement'!F31)/'Income Statement'!F31 -> 0.023755009 | I31: =AVERAGE(E31:G31) -> 0.057785328 | J31: =AVERAGE(D31:G31) -> 0.056833686 | L31: {=_xlfn.IFS($N$4="Bull",T31, $N$4="Bear",AA31, $N$4="Base",AH31)} -> 0.032 | M31: {=_xlfn.IFS($N$4="Bull",U31, $N$4="Bear",AB31, $N$4="Base",AI31)} -> 0.034 | N31: {=_xlfn.IFS($N$4="Bull",V31, $N$4="Bear",AC31, $N$4="Base",AJ31)} -> 0.041 | O31: {=_xlfn.IFS($N$4="Bull",W31, $N$4="Bear",AD31, $N$4="Base",AK31)} -> 0.055 | P31: {=_xlfn.IFS($N$4="Bull",X31, $N$4="Bear",AE31, $N$4="Base",AL31)} -> 0.055 | T31: 0.03 | U31: 0.032 | V31: 0.038 | W31: 0.041 | X31: 0.044 | AA31: 0.02 | AB31: 0.022 | AC31: 0.025 | AD31: 0.025 | AE31: 0.02 | AH31: 0.032 | AI31: 0.034 | AJ31: 0.041 | AK31: 0.055 | AL31: 0.055
B32: Other Operations | D32: =('Income Statement'!D32-'Income Statement'!C32)/'Income Statement'!C32 -> -0.52631579 | E32: =('Income Statement'!E32-'Income Statement'!D32)/'Income Statement'!D32 -> 0.11111111 | F32: =('Income Statement'!F32-'Income Statement'!E32)/'Income Statement'!E32 -> 6.9 | G32: =('Income Statement'!G32-'Income Statement'!F32)/'Income Statement'!F32 -> -0.56962025 | I32: =AVERAGE(E32:G32) -> 2.1471636 | J32: =AVERAGE(D32:G32) -> 1.4787938 | L32: {=_xlfn.IFS($N$4="Bull",T32, $N$4="Bear",AA32, $N$4="Base",AH33)} -> 0 | M32: {=_xlfn.IFS($N$4="Bull",U32, $N$4="Bear",AB32, $N$4="Base",AI33)} -> 0 | N32: {=_xlfn.IFS($N$4="Bull",V32, $N$4="Bear",AC32, $N$4="Base",AJ33)} -> 0 | O32: {=_xlfn.IFS($N$4="Bull",W32, $N$4="Bear",AD32, $N$4="Base",AK33)} -> 0 | P32: {=_xlfn.IFS($N$4="Bull",X32, $N$4="Bear",AE32, $N$4="Base",AL33)} -> 0 | T32: -0.15 | U32: -0.1 | V32: 0.05 | W32: 0 | X32: 0.03 | AA32: 0 | AB32: 0 | AC32: 0 | AD32: -0.05 | AE32: -0.1 | AH32: -0.2 | AI32: -0.15 | AJ32: -0.13 | AK32: -0.1 | AL32: -0.07
B33: Other Revenues | D33: =('Income Statement'!D33-'Income Statement'!C33)/'Income Statement'!C33 -> -0.15228426 | E33: =('Income Statement'!E33-'Income Statement'!D33)/'Income Statement'!D33 -> -1 | F33: ='Income Statement'!F33 -> 0 | G33: ='Income Statement'!G33 -> 0 | I33: =AVERAGE(E33:G33) -> -0.33333333 | J33: =AVERAGE(D33:G33) -> -0.28807107 | L33: {=_xlfn.IFS($N$4="Bull",T33, $N$4="Bear",AA33, $N$4="Base",AH33)} -> 0 | M33: {=_xlfn.IFS($N$4="Bull",U33, $N$4="Bear",AB33, $N$4="Base",AI33)} -> 0 | N33: {=_xlfn.IFS($N$4="Bull",V33, $N$4="Bear",AC33, $N$4="Base",AJ33)} -> 0 | O33: {=_xlfn.IFS($N$4="Bull",W33, $N$4="Bear",AD33, $N$4="Base",AK33)} -> 0 | P33: {=_xlfn.IFS($N$4="Bull",X33, $N$4="Bear",AE33, $N$4="Base",AL33)} -> 0 | T33: 0 | U33: 0 | V33: 0 | W33: 0 | X33: 0 | AA33: 0 | AB33: 0 | AC33: 0 | AD33: 0 | AE33: 0 | AH33: =G33 -> 0 | AI33: =G33 -> 0 | AJ33: =G33 -> 0 | AK33: =G33 -> 0 | AL33: =G33 -> 0
B34: Intercompany Eliminations | D34: =('Income Statement'!D34-'Income Statement'!C34)/'Income Statement'!C34 -> 0.24963716 | E34: =('Income Statement'!E34-'Income Statement'!D34)/'Income Statement'!D34 -> 0.94541231 | F34: =('Income Statement'!F34-'Income Statement'!E34)/'Income Statement'!E34 -> -0.031243781 | G34: =('Income Statement'!G34-'Income Statement'!F34)/'Income Statement'!F34 -> 0.16762531 | I34: =AVERAGE(E34:G34) -> 0.36059795 | J34: =AVERAGE(D34:G34) -> 0.33285775 | L34: {=_xlfn.IFS($N$4="Bull",T34, $N$4="Bear",AA34, $N$4="Base",AH34)} -> 0 | M34: {=_xlfn.IFS($N$4="Bull",U34, $N$4="Bear",AB34, $N$4="Base",AI34)} -> 0 | N34: {=_xlfn.IFS($N$4="Bull",V34, $N$4="Bear",AC34, $N$4="Base",AJ34)} -> 0 | O34: {=_xlfn.IFS($N$4="Bull",W34, $N$4="Bear",AD34, $N$4="Base",AK34)} -> 0 | P34: {=_xlfn.IFS($N$4="Bull",X34, $N$4="Bear",AE34, $N$4="Base",AL34)} -> 0 | T34: 0.3329 | U34: 0.3329 | V34: 0.3329 | W34: 0.3329 | X34: 0.3329 | AA34: 0 | AB34: 0 | AC34: 0 | AD34: 0.02 | AE34: 0.03
B35: Net investment income | D35: =('Income Statement'!D37-'Income Statement'!C37)/'Income Statement'!C37 -> -0.25435765 | E35: =('Income Statement'!E37-'Income Statement'!D37)/'Income Statement'!D37 -> 0.0095238095 | F35: =('Income Statement'!F37-'Income Statement'!E37)/'Income Statement'!E37 -> -0.16552316 | G35: =('Income Statement'!G37-'Income Statement'!F37)/'Income Statement'!F37 -> 0.075025694 | I35: =AVERAGE(E35:G35) -> -0.026991218 | J35: =AVERAGE(D35:G35) -> -0.083832826 | L35: {=_xlfn.IFS($N$4="Bull",T35, $N$4="Bear",AA35, $N$4="Base",AH35)} -> 0.055 | M35: {=_xlfn.IFS($N$4="Bull",U35, $N$4="Bear",AB35, $N$4="Base",AI35)} -> 0.042 | N35: {=_xlfn.IFS($N$4="Bull",V35, $N$4="Bear",AC35, $N$4="Base",AJ35)} -> 0.035 | O35: {=_xlfn.IFS($N$4="Bull",W35, $N$4="Bear",AD35, $N$4="Base",AK35)} -> 0.02 | P35: {=_xlfn.IFS($N$4="Bull",X35, $N$4="Bear",AE35, $N$4="Base",AL35)} -> -0.03 | AA35: 0.03 | AB35: 0.02 | AC35: 0.01 | AD35: 0 | AE35: -0.05 | AH35: 0.055 | AI35: 0.042 | AJ35: 0.035 | AK35: 0.02 | AL35: -0.03
A37: x | B37: Benefits and expenses
B38: Pharmacy and other service costs | C38: ='Income Statement'!C40/'Income Statement'!C38 -> 0.67528924 | D38: ='Income Statement'!D40/'Income Statement'!D38 -> 0.69153981 | E38: ='Income Statement'!E40/'Income Statement'!E38 -> 0.68522777 | F38: ='Income Statement'!F40/'Income Statement'!F38 -> 0.73854104 | G38: ='Income Statement'!G40/'Income Statement'!G38 -> 0.78206984 | I38: =AVERAGE(E38:G38) -> 0.73527955 | J38: =AVERAGE(C38:G38) -> 0.71453354 | L38: {=_xlfn.IFS($N$4="Bull",T38, $N$4="Bear",AA38, $N$4="Base",AH38)} -> 0.77 | M38: {=_xlfn.IFS($N$4="Bull",V38, $N$4="Bear",AB38, $N$4="Base",AI38)} -> 0.76 | N38: {=_xlfn.IFS($N$4="Bull",W38, $N$4="Bear",AC38, $N$4="Base",AJ38)} -> 0.75 | O38: {=_xlfn.IFS($N$4="Bull",W38, $N$4="Bear",AD38, $N$4="Base",AK38)} -> 0.74 | P38: {=_xlfn.IFS($N$4="Bull",X38, $N$4="Bear",AE38, $N$4="Base",AL38)} -> 0.73 | T38: 0.73 | U38: 0.74 | V38: 0.72 | W38: 0.7075 | X38: 0.7075 | AA38: 0.79 | AB38: 0.795 | AC38: 0.8 | AD38: 0.805 | AE38: 0.81 | AH38: 0.77 | AI38: 0.76 | AJ38: 0.75 | AK38: 0.74 | AL38: 0.73
B39: Medical costs and other benefit expenses | C39: ='Income Statement'!C41/'Income Statement'!C38 -> 0.19279863 | D39: ='Income Statement'!D41/'Income Statement'!D38 -> 0.17841078 | E39: ='Income Statement'!E41/'Income Statement'!E38 -> 0.18583463 | F39: ='Income Statement'!F41/'Income Statement'!F38 -> 0.15639302 | G39: ='Income Statement'!G41/'Income Statement'!G38 -> 0.12495089 | I39: =AVERAGE(E39:G39) -> 0.15572618 | J39: =AVERAGE(C39:G39) -> 0.16767759 | L39: {=_xlfn.IFS($N$4="Bull",T39, $N$4="Bear",AA39, $N$4="Base",AH39)} -> 0.14 | M39: {=_xlfn.IFS($N$4="Bull",U39, $N$4="Bear",AB39, $N$4="Base",AI39)} -> 0.14 | N39: {=_xlfn.IFS($N$4="Bull",V39, $N$4="Bear",AC39, $N$4="Base",AJ39)} -> 0.13 | O39: {=_xlfn.IFS($N$4="Bull",W39, $N$4="Bear",AD39, $N$4="Base",AK39)} -> 0.12 | P39: {=_xlfn.IFS($N$4="Bull",X39, $N$4="Bear",AE39, $N$4="Base",AL39)} -> 0.13 | T39: 0.124 | U39: 0.123 | V39: 0.121 | W39: 0.12 | X39: 0.119 | AA39: 0.13 | AB39: 0.132 | AC39: 0.135 | AD39: 0.137 | AE39: 0.14 | AH39: 0.14 | AI39: 0.14 | AJ39: 0.13 | AK39: 0.12 | AL39: 0.13
B40: Selling, general and administrative expenses | C40: ='Income Statement'!C42/'Income Statement'!C38 -> 0.074851503 | D40: ='Income Statement'!D42/'Income Statement'!D38 -> 0.073046157 | E40: ='Income Statement'!E42/'Income Statement'!E38 -> 0.075907101 | F40: ='Income Statement'!F42/'Income Statement'!F38 -> 0.06006774 | G40: ='Income Statement'!G42/'Income Statement'!G38 -> 0.053172063 | I40: =AVERAGE(E40:G40) -> 0.063048968 | J40: =AVERAGE(C40:G40) -> 0.067408913 | L40: {=_xlfn.IFS($N$4="Bull",T40, $N$4="Bear",AA40, $N$4="Base",AH40)} -> 0.06 | M40: {=_xlfn.IFS($N$4="Bull",U40, $N$4="Bear",AB40, $N$4="Base",AI40)} -> 0.063 | N40: {=_xlfn.IFS($N$4="Bull",V40, $N$4="Bear",AC40, $N$4="Base",AJ40)} -> 0.062 | O40: {=_xlfn.IFS($N$4="Bull",W40, $N$4="Bear",AD40, $N$4="Base",AK40)} -> 0.054 | P40: {=_xlfn.IFS($N$4="Bull",X40, $N$4="Bear",AE40, $N$4="Base",AL40)} -> 0.051 | T40: 0.051 | U40: 0.0495 | V40: 0.048 | W40: 0.047 | X40: 0.047 | AA40: 0.056 | AB40: 0.057 | AC40: 0.058 | AD40: 0.059 | AE40: 0.06 | AH40: 0.06 | AI40: 0.063 | AJ40: 0.062 | AK40: 0.054 | AL40: 0.051
B41: Amortization of acquired intangible assets | C41: ='Income Statement'!C43/'Income Statement'!C38 -> 0.011477613 | D41: ='Income Statement'!D43/'Income Statement'!D38 -> 0.010392431 | E41: ='Income Statement'!E43/'Income Statement'!E38 -> 0.0093155455 | F41: ='Income Statement'!F43/'Income Statement'!F38 -> 0.0068913609 | G41: ='Income Statement'!G43/'Income Statement'!G38 -> 0.0063404874 | I41: =AVERAGE(E41:G41) -> 0.007515798 | J41: =AVERAGE(C41:G41) -> 0.0088834876 | L41: {=_xlfn.IFS($N$4="Bull",T41, $N$4="Bear",AA41, $N$4="Base",AH41)} -> 0.0062 | M41: {=_xlfn.IFS($N$4="Bull",U41, $N$4="Bear",AB41, $N$4="Base",AI41)} -> 0.006 | N41: {=_xlfn.IFS($N$4="Bull",V41, $N$4="Bear",AC41, $N$4="Base",AJ41)} -> 0.0058 | O41: {=_xlfn.IFS($N$4="Bull",W41, $N$4="Bear",AD41, $N$4="Base",AK41)} -> 0.0056 | P41: {=_xlfn.IFS($N$4="Bull",X41, $N$4="Bear",AE41, $N$4="Base",AL41)} -> 0.0056 | T41: 0.0055 | U41: 0.005 | V41: 0.0045 | W41: 0.004 | X41: 0.0038 | AA41: 0.0065 | AB41: 0.0063 | AC41: 0.0061 | AD41: 0.006 | AE41: 0.006 | AH41: 0.0062 | AI41: 0.006 | AJ41: 0.0058 | AK41: 0.0056 | AL41: 0.0056
B42: Debt extinguishment costs | C42: ='Income Statement'!C46/'Income Statement'!C38 -> -0.00080998173 | D42: ='Income Statement'!D46/'Income Statement'!D38 -> 0 | E42: ='Income Statement'!E46/'Income Statement'!E38 -> 0 | F42: ='Income Statement'!F46/'Income Statement'!F38 -> 0 | G42: ='Income Statement'!G46/'Income Statement'!G38 -> 0 | I42: =AVERAGE(E42:G42) -> 0 | J42: =AVERAGE(C42:G42) -> -0.00016199635 | L42: {=_xlfn.IFS($N$4="Bull",T42, $N$4="Bear",AA42, $N$4="Base",AH42)} -> 0 | M42: {=_xlfn.IFS($N$4="Bull",U42, $N$4="Bear",AB42, $N$4="Base",AI42)} -> 0 | N42: {=_xlfn.IFS($N$4="Bull",V42, $N$4="Bear",AC42, $N$4="Base",AJ42)} -> 0 | O42: {=_xlfn.IFS($N$4="Bull",W42, $N$4="Bear",AD42, $N$4="Base",AK42)} -> -0.00016199635 | P42: {=_xlfn.IFS($N$4="Bull",X42, $N$4="Bear",AE42, $N$4="Base",AL42)} -> 0 | T42: 0 | U42: 0 | V42: 0 | W42: 0 | X42: 0 | AA42: 0 | AB42: 0 | AC42: 0 | AD42: -0.0002 | AE42: 0 | AH42: =G42 -> 0 | AI42: =H42 -> 0 | AJ42: =I42 -> 0 | AK42: =J42 -> -0.00016199635 | AL42: =K42 -> 0
B43: Interest expense and other | C43: ='Income Statement'!C47/'Income Statement'!C38 -> -0.006939418 | D43: ='Income Statement'!D47/'Income Statement'!D38 -> -0.0068027211 | E43: ='Income Statement'!E47/'Income Statement'!E38 -> -0.007405321 | F43: ='Income Statement'!F47/'Income Statement'!F38 -> -0.0058068719 | G43: ='Income Statement'!G47/'Income Statement'!G38 -> -0.0051218625 | I43: =AVERAGE(E43:G43) -> -0.0061113518 | J43: =AVERAGE(C43:G43) -> -0.0064152389 | L43: {=_xlfn.IFS($N$4="Bull",T43, $N$4="Bear",AA43, $N$4="Base",AH43)} -> 1272.7944 | M43: {=_xlfn.IFS($N$4="Bull",U43, $N$4="Bear",AB43, $N$4="Base",AI43)} -> 1070.5444 | N43: {=_xlfn.IFS($N$4="Bull",V43, $N$4="Bear",AC43, $N$4="Base",AJ43)} -> 890.56893 | O43: {=_xlfn.IFS($N$4="Bull",W43, $N$4="Bear",AD43, $N$4="Base",AK43)} -> 760.51813 | P43: {=_xlfn.IFS($N$4="Bull",X43, $N$4="Bear",AE43, $N$4="Base",AL43)} -> 664.34232 | T43: ='Debt Schedule'!F266 -> 1272.7944 | U43: ='Debt Schedule'!G266 -> 1070.5444 | V43: ='Debt Schedule'!H266 -> 890.56893 | W43: ='Debt Schedule'!I266 -> 760.51813 | X43: ='Debt Schedule'!J266 -> 664.34232 | AA43: ='Debt Schedule'!F266 -> 1272.7944 | AB43: ='Debt Schedule'!G266 -> 1070.5444 | AC43: ='Debt Schedule'!H266 -> 890.56893 | AD43: ='Debt Schedule'!I266 -> 760.51813 | AE43: ='Debt Schedule'!J266 -> 664.34232 | AH43: ='Debt Schedule'!F266 -> 1272.7944 | AI43: ='Debt Schedule'!G266 -> 1070.5444 | AJ43: ='Debt Schedule'!H266 -> 890.56893 | AK43: ='Debt Schedule'!I266 -> 760.51813 | AL43: ='Debt Schedule'!J266 -> 664.34232
B44: Net gain (loss) on sale of businesses | C44: ='Income Statement'!C48/'Income Statement'!C38 -> 0 | D44: ='Income Statement'!D48/'Income Statement'!D38 -> 0.0092069401 | E44: ='Income Statement'!E48/'Income Statement'!E38 -> -0.007676747 | F44: ='Income Statement'!F48/'Income Statement'!F38 -> 9.7118416e-05 | G44: ='Income Statement'!G48/'Income Statement'!G38 -> 4.7289924e-05 | I44: =AVERAGE(E44:G44) -> -0.0025107795 | J44: =AVERAGE(C44:G44) -> 0.00033492029 | L44: {=_xlfn.IFS($N$4="Bull",T44, $N$4="Bear",AA44, $N$4="Base",AH44)} -> -0.001 | M44: {=_xlfn.IFS($N$4="Bull",U44, $N$4="Bear",AB44, $N$4="Base",AI44)} -> -0.001 | N44: {=_xlfn.IFS($N$4="Bull",V44, $N$4="Bear",AC44, $N$4="Base",AJ44)} -> -0.001 | O44: {=_xlfn.IFS($N$4="Bull",W44, $N$4="Bear",AD44, $N$4="Base",AK44)} -> -0.001 | P44: {=_xlfn.IFS($N$4="Bull",X44, $N$4="Bear",AE44, $N$4="Base",AL44)} -> -0.001 | T44: 0.1 | U44: 0.1 | V44: 0.1 | W44: 0.1 | X44: 0.1 | AA44: 0 | AB44: 0 | AC44: 0 | AD44: 0 | AE44: 0 | AH44: -0.001 | AI44: -0.001 | AJ44: -0.001 | AK44: -0.001 | AL44: -0.001
B45: Net investment losses | C45: ='Income Statement'!C49/'Income Statement'!C38 -> 0.0011259321 | D45: ='Income Statement'!D49/'Income Statement'!D38 -> -0.0027421392 | E45: ='Income Statement'!E49/'Income Statement'!E38 -> -0.00039945715 | F45: ='Income Statement'!F49/'Income Statement'!F38 -> -0.011075546 | G45: ='Income Statement'!G49/'Income Statement'!G38 -> -8.7304474e-05 | I45: =AVERAGE(E45:G45) -> -0.0038541025 | J45: =AVERAGE(C45:G45) -> -0.002635703 | L45: {=_xlfn.IFS($N$4="Bull",T45, $N$4="Bear",AA45, $N$4="Base",AH45)} -> -0.002 | M45: {=_xlfn.IFS($N$4="Bull",U45, $N$4="Bear",AB45, $N$4="Base",AI45)} -> -0.003 | N45: {=_xlfn.IFS($N$4="Bull",V45, $N$4="Bear",AC45, $N$4="Base",AJ45)} -> -0.004 | O45: {=_xlfn.IFS($N$4="Bull",W45, $N$4="Bear",AD45, $N$4="Base",AK45)} -> -0.005 | P45: {=_xlfn.IFS($N$4="Bull",X45, $N$4="Bear",AE45, $N$4="Base",AL45)} -> -0.006 | T45: -0.15 | U45: -0.2 | V45: -0.25 | W45: -0.3 | X45: -0.35 | AA45: -0.15 | AB45: -0.25 | AC45: -0.3 | AD45: -0.45 | AE45: -0.55 | AH45: -0.002 | AI45: -0.003 | AJ45: -0.004 | AK45: -0.005 | AL45: -0.006
...

Sheet Income Statement
B2: Consolidated Statements of Income | C2: Historical | H2: Projected
B3: $ in Millions except Per Share Data | C3: 2021 | D3: =C3+1 -> 2022 | E3: =D3+1 -> 2023 | F3: =E3+1 -> 2024 | G3: =F3+1 -> 2025 | H3: =G3+1 -> 2026 | I3: =H3+1 -> 2027 | J3: =I3+1 -> 2028 | K3: =J3+1 -> 2029 | L3: =K3+1 -> 2030
B4: Revenues
B5: Products ( Pharmacy Revenues) (ASC 606)
B6: Network Revenues | C6: 64992 | D6: 64946 | E6: 67514 | F6: 105340 | G6: 125573 | H6: =(Assumptions!L6*'Income Statement'!G6)+'Income Statement'!G6 -> 143153.22 | I6: =(Assumptions!M6*'Income Statement'!H6)+'Income Statement'!H6 -> 160331.61 | J6: =(Assumptions!N6*'Income Statement'!I6)+'Income Statement'!I6 -> 173158.13 | K6: =(Assumptions!O6*'Income Statement'!J6)+'Income Statement'!J6 -> 184413.41 | L6: =(Assumptions!P6*'Income Statement'!K6)+'Income Statement'!K6 -> 196400.29
B7: Home Delivery and Specialty | C7: 54391 | D7: 61283 | E7: 65732 | F7: 72476 | G7: 80492 | H7: =(Assumptions!L7*'Income Statement'!G7)+'Income Statement'!G7 -> 89587.596 | I7: =(Assumptions!M7*'Income Statement'!H7)+'Income Statement'!H7 -> 98546.356 | J7: =(Assumptions!N7*'Income Statement'!I7)+'Income Statement'!I7 -> 107908.26 | K7: =(Assumptions!O7*'Income Statement'!J7)+'Income Statement'!J7 -> 116540.92 | L7: =(Assumptions!P7*'Income Statement'!K7)+'Income Statement'!K7 -> 125864.19
B8: Other Revenues | C8: 6428 | D8: 6753 | E8: 9047 | F8: 11545 | G8: 13329 | H8: =(Assumptions!L8*'Income Statement'!G8)+'Income Statement'!G8 -> 15188.396 | I8: =(Assumptions!M8*'Income Statement'!H8)+'Income Statement'!H8 -> 16980.626 | J8: =(Assumptions!N8*'Income Statement'!I8)+'Income Statement'!I8 -> 18848.495 | K8: =(Assumptions!O8*'Income Statement'!J8)+'Income Statement'!J8 -> 20827.587 | L8: =(Assumptions!P8*'Income Statement'!K8)+'Income Statement'!K8 -> 23014.484
B9: Other Operations | C9: 0 | D9: 0 | E9: 0 | F9: 60 | G9: 54 | H9: =(Assumptions!L9*'Income Statement'!G9)+'Income Statement'!G9 -> 48.6 | I9: =(Assumptions!M9*'Income Statement'!H9)+'Income Statement'!H9 -> 43.74 | J9: =(Assumptions!N9*'Income Statement'!I9)+'Income Statement'!I9 -> 39.366 | K9: =(Assumptions!O9*'Income Statement'!J9)+'Income Statement'!J9 -> 35.4294 | L9: =(Assumptions!P9*'Income Statement'!K9)+'Income Statement'!K9 -> 31.88646
B10: Intercompany Eliminatioons | C10: -4398 | D10: -4416 | E10: -5050 | F10: -4059 | G10: -2776 | H10: =(Assumptions!L10*'Income Statement'!G10)+'Income Statement'!G10 -> -2095.88 | I10: =(Assumptions!M10*'Income Statement'!H10)+'Income Statement'!H10 -> -1666.2246 | J10: =(Assumptions!N10*'Income Statement'!I10)+'Income Statement'!I10 -> -1379.634 | K10: =(Assumptions!O10*'Income Statement'!J10)+'Income Statement'!J10 -> -1214.0779 | L10: =(Assumptions!P10*'Income Statement'!K10)+'Income Statement'!K10 -> -1068.3885
B11: Total Pharmacy Revenue | C11: =SUM(C6:C10) -> 121413 | D11: =SUM(D6:D10) -> 128566 | E11: =SUM(E6:E10) -> 137243 | F11: =SUM(F6:F10) -> 185362 | G11: =SUM(G6:G10) -> 216672 | H11: =SUM(H6:H10) -> 245881.93 | I11: =SUM(I6:I10) -> 274236.1 | J11: =SUM(J6:J10) -> 298574.62 | ... L11: =SUM(L6:L10) -> 344242.46
B12: Insurance Premiums (ASC 944)
B13: Cigna Healthcare
B14: U.S Commercial
B15: Insured | C15: 14315 | D15: 15199 | E15: 16490 | F15: 17576 | G15: 18852 | H15: =(Assumptions!L15*'Income Statement'!G15)+'Income Statement'!G15 -> 19417.56 | I15: =(Assumptions!M15*'Income Statement'!H15)+'Income Statement'!H15 -> 20077.757 | J15: =(Assumptions!N15*'Income Statement'!I15)+'Income Statement'!I15 -> 20760.401 | K15: =(Assumptions!O15*'Income Statement'!J15)+'Income Statement'!J15 -> 21798.421 | L15: =(Assumptions!P15*'Income Statement'!K15)+'Income Statement'!K15 -> 22888.342
B16: Stop Loss | C16: 4868 | D16: 5461 | E16: 6143 | F16: 6744 | G16: 7599 | H16: =(Assumptions!L16*'Income Statement'!G16)+'Income Statement'!G16 -> 8548.875 | I16: =(Assumptions!M16*'Income Statement'!H16)+'Income Statement'!H16 -> 9531.9956 | J16: =(Assumptions!N16*'Income Statement'!I16)+'Income Statement'!I16 -> 10580.515 | K16: =(Assumptions!O16*'Income Statement'!J16)+'Income Statement'!J16 -> 11691.469 | L16: =(Assumptions!P16*'Income Statement'!K16)+'Income Statement'!K16 -> 12919.074
B17: Other | C17: 1290 | D17: 1418 | E17: 5088 | F17: 3951 | G17: 3371 | H17: =(Assumptions!L17*'Income Statement'!G17)+'Income Statement'!G17 -> 2865.35 | I17: =(Assumptions!M17*'Income Statement'!H17)+'Income Statement'!H17 -> 2578.815 | J17: =(Assumptions!N17*'Income Statement'!I17)+'Income Statement'!I17 -> 2372.5098 | K17: =(Assumptions!O17*'Income Statement'!J17)+'Income Statement'!J17 -> 2253.8843 | L17: =(Assumptions!P17*'Income Statement'!K17)+'Income Statement'!K17 -> 2141.1901
B18: U.S Government
B19: Medicare Advantage | C19: 8362 | D19: 7896 | E19: 8771 | F19: 8679 | G19: 2363 | H19: =(Assumptions!L19*'Income Statement'!G19)+'Income Statement'!G19 -> 2363 | I19: =(Assumptions!M19*'Income Statement'!H19)+'Income Statement'!H19 -> 2363 | J19: =(Assumptions!N19*'Income Statement'!I19)+'Income Statement'!I19 -> 2363 | K19: =(Assumptions!O19*'Income Statement'!J19)+'Income Statement'!J19 -> 2363 | L19: =(Assumptions!P19*'Income Statement'!K19)+'Income Statement'!K19 -> 2363
B20: Medicare Part D | C20: 1499 | D20: 1224 | E20: 0 | F20: 0 | G20: 0 | H20: =(Assumptions!L20*'Income Statement'!G20)+'Income Statement'!G20 -> 0 | I20: =(Assumptions!M20*'Income Statement'!H20)+'Income Statement'!H20 -> 0 | J20: =(Assumptions!N20*'Income Statement'!I20)+'Income Statement'!I20 -> 0 | K20: =(Assumptions!O20*'Income Statement'!J20)+'Income Statement'!J20 -> 0 | L20: =(Assumptions!P20*'Income Statement'!K20)+'Income Statement'!K20 -> 0
B21: Other | C21: 4815 | D21: 3990 | E21: 4095 | F21: 4938 | G21: 3366 | H21: =(Assumptions!L21*'Income Statement'!G21)+'Income Statement'!G21 -> 3433.32 | I21: =(Assumptions!M21*'Income Statement'!H21)+'Income Statement'!H21 -> 3501.9864 | J21: =(Assumptions!N21*'Income Statement'!I21)+'Income Statement'!I21 -> 3572.0261 | K21: =(Assumptions!O21*'Income Statement'!J21)+'Income Statement'!J21 -> 3643.4667 | L21: =(Assumptions!P21*'Income Statement'!K21)+'Income Statement'!K21 -> 3716.336
B22: International Health | C22: 2588 | D22: 2906 | E22: 3295 | F22: 3624 | G22: 4126 | H22: =(Assumptions!L22*'Income Statement'!G22)+'Income Statement'!G22 -> 4167.26 | I22: =(Assumptions!M22*'Income Statement'!H22)+'Income Statement'!H22 -> 4208.9326 | J22: =(Assumptions!N22*'Income Statement'!I22)+'Income Statement'!I22 -> 4293.1113 | K22: =(Assumptions!O22*'Income Statement'!J22)+'Income Statement'!J22 -> 4378.9735 | L22: =(Assumptions!P22*'Income Statement'!K22)+'Income Statement'!K22 -> 4422.7632
B23: Total Cigna Healthcare | C23: =SUM(C15:C22) -> 37737 | D23: =SUM(D15:D22) -> 38094 | E23: =SUM(E15:E22) -> 43882 | F23: =SUM(F15:F22) -> 45512 | G23: =SUM(G15:G22) -> 39677 | H23: =SUM(H15:H22) -> 40795.365 | I23: =SUM(I15:I22) -> 42262.487 | J23: =SUM(J15:J22) -> 43941.563 | ... L23: =SUM(L15:L22) -> 48450.705
B24: Divested International Businesses | C24: 3205 | D24: 1596 | E24: 0 | F24: 0 | G24: 0 | H24: =(Assumptions!L24*'Income Statement'!G24)+'Income Statement'!G24 -> 0 | I24: =(Assumptions!M24*'Income Statement'!H24)+'Income Statement'!H24 -> 0 | J24: =(Assumptions!N24*'Income Statement'!I24)+'Income Statement'!I24 -> 0 | K24: =(Assumptions!O24*'Income Statement'!J24)+'Income Statement'!J24 -> 0 | L24: =(Assumptions!P24*'Income Statement'!K24)+'Income Statement'!K24 -> 0
B25: Domestic Disability; Life and accident | C25: 0 | D25: 0 | E25: 0 | F25: 0 | G25: 0 | H25: =(Assumptions!L25*'Income Statement'!G25)+'Income Statement'!G25 -> 0 | I25: =(Assumptions!M25*'Income Statement'!H25)+'Income Statement'!H25 -> 0 | J25: =(Assumptions!N25*'Income Statement'!I25)+'Income Statement'!I25 -> 0 | K25: =(Assumptions!O25*'Income Statement'!J25)+'Income Statement'!J25 -> 0 | L25: =(Assumptions!P25*'Income Statement'!K25)+'Income Statement'!K25 -> 0
B26: Other | C26: 221 | D26: 224 | E26: 281 | F26: 380 | G26: 288 | H26: =(Assumptions!L26*'Income Statement'!G26)+'Income Statement'!G26 -> 319.12115 | I26: =(Assumptions!M26*'Income Statement'!H26)+'Income Statement'!H26 -> 353.60524 | J26: =(Assumptions!N26*'Income Statement'!I26)+'Income Statement'!I26 -> 391.81567 | K26: =(Assumptions!O26*'Income Statement'!J26)+'Income Statement'!J26 -> 434.15509 | L26: =(Assumptions!P26*'Income Statement'!K26)+'Income Statement'!K26 -> 481.0697
B27: Intercompany Eliminations | C27: -9 | D27: 1 | E27: 74 | F27: 104 | G27: 296 | H27: =(Assumptions!L27*'Income Statement'!G27)+'Income Statement'!G27 -> 296 | I27: =(Assumptions!M27*'Income Statement'!H27)+'Income Statement'!H27 -> 296 | J27: =(Assumptions!N27*'Income Statement'!I27)+'Income Statement'!I27 -> 296 | K27: =(Assumptions!O27*'Income Statement'!J27)+'Income Statement'!J27 -> 296 | L27: =(Assumptions!P27*'Income Statement'!K27)+'Income Statement'!K27 -> 296
B28: Total Premiums | C28: =SUM(C23:C27) -> 41154 | D28: =SUM(D23:D27) -> 39915 | E28: =SUM(E23:E27) -> 44237 | F28: =SUM(F23:F27) -> 45996 | G28: =SUM(G23:G27) -> 40261 | H28: =SUM(H23:H27) -> 41410.486 | I28: =SUM(I23:I27) -> 42912.092 | J28: =SUM(J23:J27) -> 44629.379 | ... L28: =SUM(L23:L27) -> 49227.774
B29: Service (Fees)(ASC 606)
B30: Evernorth Health Services | C30: 6070 | D30: 7234 | E30: 10965 | F30: 12591 | G30: 15417 | H30: =(Assumptions!L30*'Income Statement'!G30)+'Income Statement'!G30 -> 18500.4 | I30: =(Assumptions!M30*'Income Statement'!H30)+'Income Statement'!H30 -> 22292.982 | J30: =(Assumptions!N30*'Income Statement'!I30)+'Income Statement'!I30 -> 26974.508 | K30: =(Assumptions!O30*'Income Statement'!J30)+'Income Statement'!J30 -> 32774.027 | L30: =(Assumptions!P30*'Income Statement'!K30)+'Income Statement'!K30 -> 39984.314
B31: Cigna Healthcare | C31: 5743 | D31: 6053 | E31: 6669 | F31: 6988 | G31: 7154 | H31: =(Assumptions!L31*'Income Statement'!G31)+'Income Statement'!G31 -> 7382.928 | I31: =(Assumptions!M31*'Income Statement'!H31)+'Income Statement'!H31 -> 7633.9476 | J31: =(Assumptions!N31*'Income Statement'!I31)+'Income Statement'!I31 -> 7946.9394 | K31: =(Assumptions!O31*'Income Statement'!J31)+'Income Statement'!J31 -> 8384.0211 | L31: =(Assumptions!P31*'Income Statement'!K31)+'Income Statement'!K31 -> 8845.1422
B32: Other Operations | C32: 19 | D32: 9 | E32: 10 | F32: 79 | G32: 34 | H32: =(Assumptions!L32*'Income Statement'!G32)+'Income Statement'!G32 -> 34 | I32: =(Assumptions!M32*'Income Statement'!H32)+'Income Statement'!H32 -> 34 | J32: =(Assumptions!N32*'Income Statement'!I32)+'Income Statement'!I32 -> 34 | K32: =(Assumptions!O32*'Income Statement'!J32)+'Income Statement'!J32 -> 34 | L32: =(Assumptions!P32*'Income Statement'!K32)+'Income Statement'!K32 -> 34
B33: Other Revenues | C33: 197 | D33: 167 | E33: 0 | F33: 0 | G33: 0 | H33: =(Assumptions!L33*'Income Statement'!G33)+'Income Statement'!G33 -> 0 | I33: =(Assumptions!M33*'Income Statement'!H33)+'Income Statement'!H33 -> 0 | J33: =(Assumptions!N33*'Income Statement'!I33)+'Income Statement'!I33 -> 0 | K33: =(Assumptions!O33*'Income Statement'!J33)+'Income Statement'!J33 -> 0 | L33: =(Assumptions!P33*'Income Statement'!K33)+'Income Statement'!K33 -> 0
B34: Intercompany Eliminations | C34: -2067 | D34: -2583 | E34: -5025 | F34: -4868 | G34: -5684 | H34: =(Assumptions!L34*'Income Statement'!G34)+'Income Statement'!G34 -> -5684 | I34: =(Assumptions!M34*'Income Statement'!H34)+'Income Statement'!H34 -> -5684 | J34: =(Assumptions!N34*'Income Statement'!I34)+'Income Statement'!I34 -> -5684 | K34: =(Assumptions!O34*'Income Statement'!J34)+'Income Statement'!J34 -> -5684 | L34: =(Assumptions!P34*'Income Statement'!K34)+'Income Statement'!K34 -> -5684
B35: Total Fees and other Revenues | C35: =SUM(C30:C34) -> 9962 | D35: =SUM(D30:D34) -> 10880 | E35: =SUM(E30:E34) -> 12619 | F35: =SUM(F30:F34) -> 14790 | G35: =SUM(G30:G34) -> 16921 | H35: =SUM(H30:H34) -> 20233.328 | I35: =SUM(I30:I34) -> 24276.93 | J35: =SUM(J30:J34) -> 29271.448 | ... L35: =SUM(L30:L34) -> 43179.456
B36: Total Revenues from External Customers | C36: =C35+C28+C11 -> 172529 | D36: =D35+D28+D11 -> 179361 | E36: =E35+E28+E11 -> 194099 | F36: =F35+F28+F11 -> 246148 | G36: =G35+G28+G11 -> 273854 | H36: =H35+H28+H11 -> 307525.75 | I36: =I35+I28+I11 -> 341425.13 | J36: =J35+J28+J11 -> 372475.45 | ... L36: =L35+L28+L11 -> 436649.69
B37: Net investment income | C37: 1549 | D37: 1155 | E37: 1166 | F37: 973 | G37: 1046 | H37: =(Assumptions!L35*'Income Statement'!G37)+'Income Statement'!G37 -> 1103.53 | I37: =(Assumptions!M35*'Income Statement'!H37)+'Income Statement'!H37 -> 1149.8783 | J37: =(Assumptions!N35*'Income Statement'!I37)+'Income Statement'!I37 -> 1190.124 | K37: =(Assumptions!O35*'Income Statement'!J37)+'Income Statement'!J37 -> 1213.9265 | L37: =(Assumptions!P35*'Income Statement'!K37)+'Income Statement'!K37 -> 1177.5087
A38: x | B38: TOTAL REVENUES | C38: =C36+C37 -> 174078 | D38: =D36+D37 -> 180516 | E38: =E36+E37 -> 195265 | F38: =F36+F37 -> 247121 | G38: =G36+G37 -> 274900 | H38: =H36+H37 -> 308629.28 | I38: =I36+I37 -> 342575 | J38: =J36+J37 -> 373665.57 | ... L38: =L36+L37 -> 437827.2
B39: Benefits and expenses
B40: Pharmacy and other service costs | C40: 117553 | D40: 124834 | E40: 133801 | F40: 182509 | G40: 214991 | H40: =Assumptions!L38*'Income Statement'!H38 -> 237644.54 | I40: =Assumptions!M38*'Income Statement'!I38 -> 260357 | J40: =Assumptions!N38*'Income Statement'!J38 -> 280249.18 | K40: =Assumptions!O38*'Income Statement'!K38 -> 299096.62 | L40: =Assumptions!P38*'Income Statement'!L38 -> 319613.86
B41: Medical costs and other benefit expenses | C41: 33562 | D41: 32206 | E41: 36287 | F41: 38648 | G41: 34349 | H41: =Assumptions!L39*'Income Statement'!H38 -> 43208.099 | I41: =Assumptions!M39*'Income Statement'!I38 -> 47960.5 | J41: =Assumptions!N39*'Income Statement'!J38 -> 48576.524 | K41: =Assumptions!O39*'Income Statement'!K38 -> 48502.154 | L41: =Assumptions!P39*'Income Statement'!L38 -> 56917.536
...

Sheet Balance Sheet
B2: Consolidated Balance Sheets | C2: Historical | H2: Projected
B3: $ in Millions | C3: 2021 | D3: =C3+1 -> 2022 | E3: =D3+1 -> 2023 | F3: =E3+1 -> 2024 | G3: =F3+1 -> 2025 | H3: =G3+1 -> 2026 | I3: =H3+1 -> 2027 | J3: =I3+1 -> 2028 | K3: =J3+1 -> 2029 | L3: =K3+1 -> 2030
B4: Assets
B5: Cash and cash equivalents | C5: 5081 | D5: 5924 | E5: 7822 | F5: 7550 | G5: 7676 | H5: =Assumptions!L57*'Income Statement'!H38 -> 9258.8783 | I5: =Assumptions!M57*'Income Statement'!I38 -> 9420.8126 | J5: =Assumptions!N57*'Income Statement'!J38 -> 9341.6393 | K5: =Assumptions!O57*'Income Statement'!K38 -> 9094.1539 | L5: =Assumptions!P57*'Income Statement'!L38 -> 9851.112
B6: Excess Cash | H6: =IF('Cash Flow Statement'!D75>0,'Cash Flow Statement'!D75,0) -> 0 | I6: =IF('Cash Flow Statement'!E75>0,'Cash Flow Statement'!E75,0) -> 0 | J6: =IF('Cash Flow Statement'!F75>0,'Cash Flow Statement'!F75,0) -> 0 | K6: =IF('Cash Flow Statement'!G75>0,'Cash Flow Statement'!G75,0) -> 9444.3024 | L6: =IF('Cash Flow Statement'!H75>0,'Cash Flow Statement'!H75,0) -> 27509.901
B7: Investments | C7: 920 | D7: 905 | E7: 925 | F7: 665 | G7: 1056 | H7: =Assumptions!L58*'Income Statement'!H38 -> 925.88783 | I7: =Assumptions!M58*'Income Statement'!I38 -> 1199.0125 | J7: =Assumptions!N58*'Income Statement'!J38 -> 1307.8295 | K7: =Assumptions!O58*'Income Statement'!K38 -> 1616.7385 | L7: =Assumptions!P58*'Income Statement'!L38 -> 1751.3088
B8: Accounts receivable, net | C8: 15071 | D8: 17218 | E8: 17722 | F8: 24227 | G8: 28768 | H8: =Assumptions!L59*'Income Statement'!H38 -> 29319.781 | I8: =Assumptions!M59*'Income Statement'!I38 -> 33401.063 | J8: =Assumptions!N59*'Income Statement'!J38 -> 37366.557 | K8: =Assumptions!O59*'Income Statement'!K38 -> 41428.923 | L8: =Assumptions!P59*'Income Statement'!L38 -> 44877.288
B9: Inventories | C9: 3722 | D9: 4777 | E9: 5645 | F9: 6692 | G9: 7338 | H9: =Assumptions!L60*'Income Statement'!H40 -> 7129.3363 | I9: =Assumptions!M60*'Income Statement'!I40 -> 8331.4241 | J9: =Assumptions!N60*'Income Statement'!J40 -> 9528.4721 | K9: =Assumptions!O60*'Income Statement'!K40 -> 10767.478 | L9: =Assumptions!P60*'Income Statement'!L40 -> 12145.327
B10: Other current assets | C10: 1283 | D10: 1296 | E10: 2169 | F10: 2732 | G10: 2976 | H10: =Assumptions!L61*'Income Statement'!H38 -> 3086.2928 | I10: =Assumptions!M61*'Income Statement'!I38 -> 3528.5225 | J10: =Assumptions!N61*'Income Statement'!J38 -> 3960.8551 | K10: =Assumptions!O61*'Income Statement'!K38 -> 4405.6123 | L10: =Assumptions!P61*'Income Statement'!L38 -> 4903.6646
B11: Assets of businesses held for sale | C11: 10057 | D11: 0 | E11: 3068 | F11: 7004 | G11: 0 | H11: 0 | I11: 0 | J11: 0 | K11: 0 | L11: 0
A12: x | B12: Total current assets | C12: =SUM(C5:C11) -> 36134 | D12: =SUM(D5:D11) -> 30120 | E12: =SUM(E5:E11) -> 37351 | F12: =SUM(F5:F11) -> 48870 | G12: =SUM(G5:G11) -> 47814 | H12: =SUM(H5:H11) -> 49720.176 | I12: =SUM(I5:I11) -> 55880.835 | J12: =SUM(J5:J11) -> 61505.353 | ... L12: =SUM(L5:L11) -> 101038.6
B13: Long-term investments | C13: 18438 | D13: 16288 | E13: 17985 | F13: 15128 | G13: 18471 | H13: =Assumptions!L63*'Income Statement'!H38 -> 24693.508 | I13: =Assumptions!M63*'Income Statement'!I38 -> 27409.514 | J13: =Assumptions!N63*'Income Statement'!J38 -> 29897.078 | K13: =Assumptions!O63*'Income Statement'!K38 -> 32338.915 | L13: =Assumptions!P63*'Income Statement'!L38 -> 35030.667 | M13: x
B14: Reinsurance recoverables | C14: 4970 | D14: 4743 | E14: 4835 | F14: 4378 | G14: 4103 | H14: =Assumptions!L64*'Income Statement'!H38 -> 4309.6992 | I14: =Assumptions!M64*'Income Statement'!I38 -> 5995.0626 | J14: =Assumptions!N64*'Income Statement'!J38 -> 7473.3114 | K14: =Assumptions!O64*'Income Statement'!K38 -> 9094.1539 | L14: =Assumptions!P64*'Income Statement'!L38 -> 10945.68
B15: Property and equipment | C15: 3692 | D15: 3774 | E15: 3695 | F15: 3654 | G15: 3651 | H15: =Assumptions!L65 -> 4321.6993 | I15: =Assumptions!M65 -> 4326.5317 | J15: =Assumptions!N65 -> 4226.9421 | K15: =Assumptions!O65 -> 3951.0496 | L15: =Assumptions!P65 -> 3644.2804
B16: Goodwill | C16: 45811 | D16: 45811 | E16: 44259 | F16: 44370 | G16: 44924 | H16: =Assumptions!$L$66 -> 44924 | I16: =Assumptions!$L$66 -> 44924 | J16: =Assumptions!$L$66 -> 44924 | K16: =Assumptions!$L$66 -> 44924 | L16: =Assumptions!$L$66 -> 44924
B17: Other intangible assets | C17: 34102 | D17: 32492 | E17: 30863 | F17: 29417 | G17: 28560 | H17: =Assumptions!L67*'Income Statement'!H38 -> 32406.074 | I17: =Assumptions!M67*'Income Statement'!I38 -> 36826.813 | J17: =Assumptions!N67*'Income Statement'!J38 -> 41103.213 | K17: =Assumptions!O67*'Income Statement'!K38 -> 45470.769 | L17: =Assumptions!P67*'Income Statement'!L38 -> 50350.128
B18: Other assets | C18: 3405 | D18: 3426 | E18: 3421 | F18: 2786 | G18: 2885 | H18: =Assumptions!L68*'Income Statement'!H38 -> 3086.2928 | I18: =Assumptions!M68*'Income Statement'!I38 -> 3083.175 | J18: =Assumptions!N68*'Income Statement'!J38 -> 2989.3246 | K18: =Assumptions!O68*'Income Statement'!K38 -> 2829.2923 | L18: =Assumptions!P68*'Income Statement'!L38 -> 2845.8768
B19: Separate account assets | C19: 8337 | D19: 7278 | E19: 7430 | F19: 7278 | G19: 7511 | H19: =Assumptions!L81*'Income Statement'!H38 -> 8178.6758 | I19: =Assumptions!M81*'Income Statement'!I38 -> 8906.9501 | J19: =Assumptions!N81*'Income Statement'!J38 -> 9528.4721 | K19: =Assumptions!O81*'Income Statement'!K38 -> 10104.615 | L19: =Assumptions!P81*'Income Statement'!L38 -> 10945.68
B20: Assets of businesses held for sale, non-current | C20: 0 | D20: 0 | E20: 2922 | F20: 0 | G20: 0 | H20: =Assumptions!L70*'Income Statement'!H38 -> 0 | I20: =Assumptions!M70*'Income Statement'!I38 -> 0 | J20: =Assumptions!N70*'Income Statement'!J38 -> 0 | K20: =Assumptions!O70*'Income Statement'!K38 -> 0 | L20: =Assumptions!P70*'Income Statement'!L38 -> 0
A21: x | B21: TOTAL ASSETS | C21: =SUM(C12:C20) -> 154889 | D21: =SUM(D12:D20) -> 143932 | E21: =SUM(E12:E20) -> 152761 | F21: =SUM(F12:F20) -> 155881 | G21: =SUM(G12:G20) -> 157919 | H21: =SUM(H12:H20) -> 171640.12 | I21: =SUM(I12:I20) -> 187352.88 | J21: =SUM(J12:J20) -> 201647.69 | ... L21: =SUM(L12:L20) -> 259724.91
B22: Liabilities
B23: Current insurance and contractholder liabilities | C23: 5318 | D23: 5385 | E23: 5514 | F23: 5388 | G23: 5710 | H23: =Assumptions!L73*'Income Statement'!H38 -> 6326.9002 | I23: =Assumptions!M73*'Income Statement'!I38 -> 6851.5001 | J23: =Assumptions!N73*'Income Statement'!J38 -> 7286.4786 | K23: =Assumptions!O73*'Income Statement'!K38 -> 7679.5077 | L23: =Assumptions!P73*'Income Statement'!L38 -> 8318.7168
B24: Pharmacy and other service costs payable | C24: 15309 | D24: 17070 | E24: 19815 | F24: 28465 | G24: 30333 | H24: =Assumptions!L74*'Income Statement'!H38 -> 31449.323 | I24: =Assumptions!M74*'Income Statement'!I38 -> 34908.393 | J24: =Assumptions!N74*'Income Statement'!J38 -> 38076.522 | K24: =Assumptions!O74*'Income Statement'!K38 -> 41186.412 | L24: =Assumptions!P74*'Income Statement'!L38 -> 44614.592
B25: Accounts payable | C25: 6655 | D25: 7775 | E25: 8553 | F25: 9294 | G25: 10659 | H25: =Assumptions!L75*'Income Statement'!H40 -> 9505.7817 | I25: =Assumptions!M75*'Income Statement'!I40 -> 10674.637 | J25: =Assumptions!N75*'Income Statement'!J40 -> 11770.466 | K25: =Assumptions!O75*'Income Statement'!K40 -> 12861.155 | L25: =Assumptions!P75*'Income Statement'!L40 -> 14063.01
B26: Revolver | H26: =IF('Cash Flow Statement'!D75<0,'Cash Flow Statement'!D75,0)*(-1) -> 8038.1749 | I26: =IF('Cash Flow Statement'!E75<0,'Cash Flow Statement'!E75,0)*(-1) -> 11022.902 | J26: =IF('Cash Flow Statement'!F75<0,'Cash Flow Statement'!F75,0)*(-1) -> 6114.0237 | K26: =IF('Cash Flow Statement'!G75<0,'Cash Flow Statement'!G75,0) -> 0 | L26: =IF('Cash Flow Statement'!H75<0,'Cash Flow Statement'!H75,0) -> 0
B27: Accrued expenses and other liabilities | C27: 7322 | D27: 8006 | E27: 9955 | F27: 9387 | G27: 9048 | H27: =Assumptions!L76*'Income Statement'!H38 -> 12345.171 | I27: =Assumptions!M76*'Income Statement'!I38 -> 13703 | J27: =Assumptions!N76*'Income Statement'!J38 -> 14946.623 | K27: =Assumptions!O76*'Income Statement'!K38 -> 16167.385 | L27: =Assumptions!P76*'Income Statement'!L38 -> 17513.088
B28: Short-term debt | C28: 2545 | D28: 2993 | E28: 2775 | F28: 3035
B29: Term March 2026 | G29: ='Debt Schedule'!E8 -> 549 | H29: ='Debt Schedule'!F8 -> 0 | I29: ='Debt Schedule'!G8 -> 0 | J29: ='Debt Schedule'!H8 -> 0 | K29: ='Debt Schedule'!I8 -> 0 | L29: ='Debt Schedule'!J8 -> 0
B30: Other, including finance leases | G30: ='Debt Schedule'!E16 -> 43 | H30: ='Debt Schedule'!F16 -> 41 | I30: ='Debt Schedule'!G16 -> 39 | J30: ='Debt Schedule'!H16 -> 37 | K30: ='Debt Schedule'!I16 -> 35 | L30: ='Debt Schedule'!J16 -> 33
B31: Liabilities of businesses held for sale | C31: 6423 | D31: 0 | E31: 2104 | F31: 2410 | G31: 0 | H31: =Assumptions!L77*'Income Statement'!H38 -> 0 | I31: =Assumptions!M77*'Income Statement'!I38 -> 0 | J31: =Assumptions!N77*'Income Statement'!J38 -> 0 | K31: =Assumptions!O77*'Income Statement'!K38 -> 0 | L31: =Assumptions!P77*'Income Statement'!L38 -> 0
A32: x | B32: Total current liabilities | C32: =SUM(C23:C31) -> 43572 | D32: =SUM(D23:D31) -> 41229 | E32: =SUM(E23:E31) -> 48716 | F32: =SUM(F23:F31) -> 57979 | G32: =SUM(G23:G31) -> 56342 | H32: =SUM(H23:H31) -> 67706.351 | I32: =SUM(I23:I31) -> 77199.432 | J32: =SUM(J23:J31) -> 78231.113 | ... L32: =SUM(L23:L31) -> 84542.406
B33: Non-current insurance and contractholder liabilities | C33: 12563 | D33: 11481 | E33: 10904 | F33: 10254 | G33: 9938 | H33: =Assumptions!L78*'Income Statement'!H38 -> 10802.025 | I33: =Assumptions!M78*'Income Statement'!I38 -> 11647.55 | J33: =Assumptions!N78*'Income Statement'!J38 -> 12330.964 | K33: =Assumptions!O78*'Income Statement'!K38 -> 13136 | L33: =Assumptions!P78*'Income Statement'!L38 -> 14229.384
B34: Deferred tax liabilities, net | C34: 8346 | D34: 7751 | E34: 7173 | F34: 6975 | G34: 7145 | H34: =Assumptions!L79*'Income Statement'!H38 -> 7715.7319 | I34: =Assumptions!M79*'Income Statement'!I38 -> 8221.8001 | J34: =Assumptions!N79*'Income Statement'!J38 -> 8594.3082 | K34: =Assumptions!O79*'Income Statement'!K38 -> 9094.1539 | L34: =Assumptions!P79*'Income Statement'!L38 -> 9851.112
B35: Other non-current liabilities | C35: 3762 | D35: 3142 | E35: 3441 | F35: 3215 | G35: 4238 | H35: =Assumptions!L80*'Income Statement'!H38 -> 4629.4391 | I35: =Assumptions!M80*'Income Statement'!I38 -> 5070.11 | J35: =Assumptions!N80*'Income Statement'!J38 -> 5418.1508 | K35: =Assumptions!O80*'Income Statement'!K38 -> 5860.6769 | L35: =Assumptions!P80*'Income Statement'!L38 -> 6348.4944
B36: Long-term debt | C36: 31125 | D36: 28100 | E36: 28155 | F36: 28937
B37: Term March 2026
B38: Finance Leases
B39: Term March 2027 | G39: ='Debt Schedule'!E34 -> 1481 | H39: ='Debt Schedule'!F34 -> 740.5 | I39: ='Debt Schedule'!G34 -> 0 | J39: ='Debt Schedule'!H34 -> 0 | K39: ='Debt Schedule'!I34 -> 0 | L39: ='Debt Schedule'!J34 -> 0
B40: Term May 2027 | G40: ='Debt Schedule'!E42 -> 260 | H40: ='Debt Schedule'!F42 -> 130 | I40: ='Debt Schedule'!G42 -> 0 | J40: ='Debt Schedule'!H42 -> 0 | K40: ='Debt Schedule'!I42 -> 0 | L40: ='Debt Schedule'!J42 -> 0
B41: Term October 2027 | G41: ='Debt Schedule'!E50 -> 599 | H41: ='Debt Schedule'!F50 -> 299.5 | I41: ='Debt Schedule'!G50 -> 0 | J41: ='Debt Schedule'!H50 -> 0 | K41: ='Debt Schedule'!I50 -> 0 | L41: ='Debt Schedule'!J50 -> 0
...

Sheet Cash Flow Statement
B2: Cash Flow Statement | D2: Projected
B3: $ in Millions | C3: 2025 | D3: 2026 | E3: 2027 | F3: 2028 | G3: 2029 | H3: 2030
B4: Cash Flow Operations
B5: Net Income | D5: ='Income Statement'!H54 -> 4011.5843 | E5: ='Income Statement'!I54 -> 8495.8178 | F5: ='Income Statement'!J54 -> 14864.33 | G5: ='Income Statement'!K54 -> 24163.093 | H5: ='Income Statement'!L54 -> 26576.419
B6: Depreciation | D6: =Calcs!H15 -> 1949.8866 | E6: =Calcs!I15 -> 2164.3521 | F6: =Calcs!J15 -> 2360.779 | G6: =Calcs!K15 -> 2553.595 | H6: =Calcs!L15 -> 2766.1452
B7: Investments | D7: =-('Balance Sheet'!H7-'Balance Sheet'!G7) -> 130.11217 | E7: =-('Balance Sheet'!I7-'Balance Sheet'!H7) -> -273.12468 | F7: =-('Balance Sheet'!J7-'Balance Sheet'!I7) -> -108.81699 | G7: =-('Balance Sheet'!K7-'Balance Sheet'!J7) -> -308.90897 | H7: =-('Balance Sheet'!L7-'Balance Sheet'!K7) -> -134.57033
B8: Receivables | D8: =-('Balance Sheet'!H8-'Balance Sheet'!G8) -> -551.78119 | E8: =-('Balance Sheet'!I8-'Balance Sheet'!H8) -> -4081.2816 | F8: =-('Balance Sheet'!J8-'Balance Sheet'!I8) -> -3965.4944 | G8: =-('Balance Sheet'!K8-'Balance Sheet'!J8) -> -4062.3661 | H8: =-('Balance Sheet'!L8-'Balance Sheet'!K8) -> -3448.3647
