Workbook

Sheet Cover
B15: By: Chineme Oriaku, Eneias Olensky, Esaa Sheikh, Jayson Soza, Karishma Shah
B17: Income Statement
B18: Debt Schedule
B19: Balance Sheet
B20: Cashflow Statement
B21: Calcs
B22: Assumptions
B23: LTM
B24: Comps

Sheet Income Statement
B2: T-Mobile US (TMUS) | C2: Historicals | H2: Projected
B3: $ in Millions | C3: 2021A | D3: 2022A | E3: 2023A | F3: 2024A | G3: 2025A | H3: 2026E | I3: 2027E | J3: 2028E | K3: 2029E | L3: 2030E
B4: Revenues
B5: Postpaid Revenue | C5: 42562 | D5: 45919 | E5: 48692 | F5: 52340 | G5: 57932
B6: Prepaid Revenue | C6: 9733 | D6: 9857 | E6: 9767 | F6: 10399 | G6: 10497
B7: Wholesale other service Revenues | C7: 6074 | D7: 5547 | E7: 4782 | F7: 3439 | G7: 2877
B8: Total Service Revenues | C8: =SUM(C5:C7) -> 58369 | D8: =SUM(D5:D7) -> 61323 | E8: =SUM(E5:E7) -> 63241 | F8: =SUM(F5:F7) -> 66178 | G8: =SUM(G5:G7) -> 71306 | H8: =G8*(1+Assumptions!L5) -> 76975.57 | I8: =H8*(1+Assumptions!M5) -> 82834.954 | J8: =I8*(1+Assumptions!N5) -> 88168.231 | K8: =J8*(1+Assumptions!O5) -> 93581.01 | L8: =K8*(1+Assumptions!P5) -> 99265.308
B9: Equipment Revenues | C9: 20727 | D9: 17130 | E9: 14138 | F9: 14263 | G9: 15972
B10: Other Revenues | C10: 1022 | D10: 1118 | E10: 1179 | F10: 959 | G10: 1031
B11: Total revenues | C11: =SUM(C8:C10) -> 80118 | D11: =SUM(D8:D10) -> 79571 | E11: =SUM(E8:E10) -> 78558 | F11: =SUM(F8:F10) -> 81400 | G11: =SUM(G8:G10) -> 88309 | H11: =G11*(1+Assumptions!L6) -> 94468.04 | I11: =H11*(1+Assumptions!M6) -> 100831.37 | J11: =I11*(1+Assumptions!N6) -> 106683.51 | K11: =J11*(1+Assumptions!O6) -> 112630.5 | L11: =K11*(1+Assumptions!P6) -> 118864.83
B12: Operating expenses
B13: Cost of services, excluding depreciation and amortization | C13: 13934 | D13: 14666 | E13: 11655 | F13: 10771 | G13: 11497 | H13: =H11*Assumptions!L7 -> 11997.441 | I13: =I11*Assumptions!M7 -> 12906.416 | J13: =J11*Assumptions!N7 -> 13335.438 | K13: =K11*Assumptions!O7 -> 13853.551 | L13: =L11*Assumptions!P7 -> 14442.076
B14: Cost of equipment sales | C14: 22671 | D14: 21540 | E14: 18533 | F14: 18882 | G14: 21277 | H14: =H11*Assumptions!L8 -> 23428.074 | I14: =I11*Assumptions!M8 -> 25459.921 | J14: =J11*Assumptions!N8 -> 26670.877 | K14: =K11*Assumptions!O8 -> 27594.472 | L14: =L11*Assumptions!P8 -> 28705.855
B15: Selling, general and administrative | C15: 20238 | D15: 21607 | E15: 21311 | F15: 20818 | G15: 23470 | H15: =H11*Assumptions!L9 -> 25034.031 | I15: =I11*Assumptions!M9 -> 27022.808 | J15: =J11*Assumptions!N9 -> 27577.687 | K15: =K11*Assumptions!O9 -> 29283.93 | L15: =L11*Assumptions!P9 -> 31083.152 | O15: Historicals | T15: Expected
B16: Gain on disposal group held for sale | C16: 0 | D16: 477 | E16: -25 | F16: 0 | G16: 0 | H16: 0 | I16: 0 | J16: 0 | K16: 0 | L16: 0 | N16: Drivers | O16: 2021A | P16: 2022A | Q16: 2023A | R16: 2024A | S16: 2025A | T16: 2026E | U16: 2027E | V16: 2028E | W16: 2029E | X16: 2030E
B17: Impairment expense | C17: 0 | D17: 1087 | E17: 0 | F17: 0 | G17: 278 | H17: 0 | I17: 0 | J17: 0 | K17: 0 | L17: 0 | N17: Total Service Revenue | O17: =Assumptions!C5 -> 0 | P17: =Assumptions!D5 -> 0.050609056 | Q17: =Assumptions!E5 -> 0.031277009 | R17: =Assumptions!F5 -> 0.046441391 | S17: =Assumptions!G5 -> 0.077487987 | T17: =Assumptions!L5 -> 0.07951042 | U17: =Assumptions!M5 -> 0.076120043 | V17: =Assumptions!N5 -> 0.064384383 | W17: =Assumptions!O5 -> 0.061391488 | X17: =Assumptions!P5 -> 0.060742008
B18: Depreciation and amortization | C18: 16383 | D18: 13651 | E18: 12818 | F18: 12919 | G18: 13508 | H18: =H11*Assumptions!L10 -> 15965.099 | I18: =I11*Assumptions!M10 -> 16233.851 | J18: =J11*Assumptions!N10 -> 16749.311 | K18: =K11*Assumptions!O10 -> 17570.358 | L18: =L11*Assumptions!P10 -> 18305.183 | N18: Total Revenues | O18: =Assumptions!C6 -> 0 | P18: =Assumptions!D6 -> -0.0068274295 | Q18: =Assumptions!E6 -> -0.012730769 | R18: =Assumptions!F6 -> 0.036177092 | S18: =Assumptions!G6 -> 0.08487715 | T18: =Assumptions!L6 -> 0.069744194 | U18: =Assumptions!M6 -> 0.067359623 | V18: =Assumptions!N6 -> 0.058038836 | W18: =Assumptions!O6 -> 0.055744253 | X18: =Assumptions!P6 -> 0.055352022
B19: Total operating expenses | C19: =SUM(C13:C18) -> 73226 | D19: =SUM(D13:D18) -> 73028 | E19: =SUM(E13:E18) -> 64292 | F19: =SUM(F13:F18) -> 63390 | G19: =SUM(G13:G18) -> 70030 | H19: =SUM(H13:H18) -> 76424.644 | I19: =SUM(I13:I18) -> 81622.995 | J19: =SUM(J13:J18) -> 84333.312 | ... L19: =SUM(L13:L18) -> 92536.266 | N19: Cost of Services, excluding Depreciation and Amortization | O19: =Assumptions!C7 -> 0.17391847 | P19: =Assumptions!D7 -> 0.18431338 | Q19: =Assumptions!E7 -> 0.14836172 | R19: =Assumptions!F7 -> 0.13232187 | S19: =Assumptions!G7 -> 0.13019058 | T19: =Assumptions!L7 -> 0.127 | U19: =Assumptions!M7 -> 0.128 | V19: =Assumptions!N7 -> 0.125 | W19: =Assumptions!O7 -> 0.123 | X19: =Assumptions!P7 -> 0.1215
B20: Operating income | C20: =C11-C19 -> 6892 | D20: =D11-D19 -> 6543 | E20: =E11-E19 -> 14266 | F20: =F11-F19 -> 18010 | G20: =G11-G19 -> 18279 | H20: =H11-H19 -> 18043.396 | I20: =I11-I19 -> 19208.376 | J20: =J11-J19 -> 22350.195 | ... L20: =L11-L19 -> 26328.559 | N20: Cost of Equipment Sales | O20: =Assumptions!C8 -> 0.28297012 | P20: =Assumptions!D8 -> 0.27070164 | Q20: =Assumptions!E8 -> 0.23591487 | R20: =Assumptions!F8 -> 0.2319656 | S20: =Assumptions!G8 -> 0.24093807 | T20: =Assumptions!H8 -> 0 | U20: =Assumptions!M8 -> 0.2525 | V20: =Assumptions!N8 -> 0.25 | W20: =Assumptions!O8 -> 0.245 | X20: =Assumptions!P8 -> 0.2415
B21: Interest expense, net | C21: -3342 | D21: -3364 | E21: -3335 | F21: -3411 | G21: -3774 | H21: =-'Debt Schedule'!D636+'Debt Schedule'!D645 -> -2034.8763 | I21: =-'Debt Schedule'!E636+'Debt Schedule'!E645 -> -1400.3891 | J21: =-'Debt Schedule'!F636+'Debt Schedule'!F645 -> -135.69274 | K21: =-'Debt Schedule'!G636+'Debt Schedule'!G645 -> 1267.9984 | L21: =-'Debt Schedule'!H636+'Debt Schedule'!H645 -> 2754.1538 | N21: Selling, General and Administrative | O21: =Assumptions!C9 -> 0.25260241 | P21: =Assumptions!D9 -> 0.27154365 | Q21: =Assumptions!E9 -> 0.27127727 | R21: =Assumptions!F9 -> 0.25574939 | S21: =Assumptions!G9 -> 0.26577133 | T21: =Assumptions!L9 -> 0.265 | U21: =Assumptions!M9 -> 0.268 | V21: =Assumptions!N9 -> 0.2585 | W21: =Assumptions!O9 -> 0.26 | X21: =Assumptions!P9 -> 0.2615
B22: Other (expense) income, net | C22: -199 | D22: -33 | E22: 68 | F22: 113 | G22: -224 | H22: =H11*Assumptions!L11 -> -47.23402 | I22: =I11*Assumptions!M11 -> -50.415686 | J22: =J11*Assumptions!N11 -> -53.341754 | K22: =K11*Assumptions!O11 -> -56.31525 | L22: =L11*Assumptions!P11 -> -59.432413 | N22: Depreciation and Amortization | O22: =Assumptions!C10 -> 0.20448588 | P22: =Assumptions!D10 -> 0.17155748 | Q22: =Assumptions!E10 -> 0.16316607 | R22: =Assumptions!F10 -> 0.15871007 | S22: =Assumptions!G10 -> 0.15296289 | T22: =Assumptions!L10 -> 0.169 | U22: =Assumptions!M10 -> 0.161 | V22: =Assumptions!N10 -> 0.157 | W22: =Assumptions!O10 -> 0.156 | X22: =Assumptions!P10 -> 0.154
B23: Income before income taxes | C23: =SUM(C20:C22) -> 3351 | D23: =SUM(D20:D22) -> 3146 | E23: =SUM(E20:E22) -> 10999 | F23: =SUM(F20:F22) -> 14712 | G23: =SUM(G20:G22) -> 14281 | H23: =SUM(H20:H22) -> 15961.285 | I23: =SUM(I20:I22) -> 17757.571 | J23: =SUM(J20:J22) -> 22161.16 | ... L23: =SUM(L20:L22) -> 29023.28 | N23: Other (expense) income, net | O23: =Assumptions!C11 -> -0.0024838363 | P23: =Assumptions!D11 -> -0.00041472396 | Q23: =Assumptions!E11 -> 0.00086560248 | R23: =Assumptions!F11 -> 0.0013882064 | S23: =Assumptions!G11 -> -0.0025365478 | T23: =Assumptions!L11 -> -0.0005 | U23: =Assumptions!M11 -> -0.0005 | V23: =Assumptions!N11 -> -0.0005 | W23: =Assumptions!O11 -> -0.0005 | X23: =Assumptions!P11 -> -0.0005
B24: Income tax expense | C24: -327 | D24: -556 | E24: -2682 | F24: -3373 | G24: -3289 | H24: =H23*Assumptions!L12 -> -1755.7414 | I24: =I23*Assumptions!M12 -> -4439.3929 | J24: =J23*Assumptions!N12 -> -4986.2611 | K24: =K23*Assumptions!O12 -> -5695.3912 | L24: =L23*Assumptions!P12 -> -6675.3544 | N24: Income Tax Expense | O24: =Assumptions!C12 -> -0.097582811 | P24: =Assumptions!D12 -> -0.17673236 | Q24: =Assumptions!E12 -> -0.24384035 | R24: =Assumptions!F12 -> -0.22926862 | S24: =Assumptions!G12 -> -0.230306 | T24: =Assumptions!L12 -> -0.11 | U24: =Assumptions!M12 -> -0.25 | V24: =Assumptions!N12 -> -0.225 | W24: =Assumptions!O12 -> -0.223 | X24: =Assumptions!P12 -> -0.23
B25: Net income | C25: =SUM(C23:C24) -> 3024 | D25: =SUM(D23:D24) -> 2590 | E25: =SUM(E23:E24) -> 8317 | F25: =SUM(F23:F24) -> 11339 | G25: =SUM(G23:G24) -> 10992 | H25: =SUM(H23:H24) -> 14205.544 | I25: =SUM(I23:I24) -> 13318.179 | J25: =SUM(J23:J24) -> 17174.899 | ... L25: =SUM(L23:L24) -> 22347.926
C28: Historicals | H28: Expected
B29: Segmented Revenue | C29: 2021A | D29: 2022A | E29: 2023A | F29: 2024A | G29: 2025A | H29: 2026E | I29: 2027E | J29: 2028E | K29: 2029E | L29: 2030E
B30: Postpaid Revenue | C30: 42562 | D30: 45919 | E30: 48692 | F30: 52340 | G30: 57932 | H30: =G30*(1+H46) -> 63725.2 | I30: =H30*(1+I46) -> 69842.819 | J30: =I30*(1+J46) -> 75430.245 | K30: =J30*(1+K46) -> 81087.513 | L30: =K30*(1+L46) -> 87006.902
B31: Prepaid Revenue | C31: 9733 | D31: 9857 | E31: 9767 | F31: 10399 | G31: 10497 | H31: =G31*(1+H47) -> 10287.06 | I31: =H31*(1+I47) -> 9978.4482 | J31: =I31*(1+J47) -> 9679.0948 | K31: =J31*(1+K47) -> 9388.7219 | L31: =K31*(1+L47) -> 9107.0603
B32: Wholesale other Revenues | C32: 6074 | D32: 5547 | E32: 4782 | F32: 3439 | G32: 2877 | H32: =G32*(1+H48) -> 2963.31 | I32: =H32*(1+I48) -> 3013.6863 | J32: =I32*(1+J48) -> 3058.8916 | K32: =J32*(1+K48) -> 3104.7749 | L32: =K32*(1+L48) -> 3151.3466
B33: Total Service Revenue | C33: =SUM(C30:C32) -> 58369 | D33: =SUM(D30:D32) -> 61323 | E33: =SUM(E30:E32) -> 63241 | F33: =SUM(F30:F32) -> 66178 | G33: =SUM(G30:G32) -> 71306 | H33: =SUM(H30:H32) -> 76975.57 | I33: =SUM(I30:I32) -> 82834.954 | J33: =SUM(J30:J32) -> 88168.231 | ... L33: =SUM(L30:L32) -> 99265.308
B34: Equipment Revenue | C34: 20727 | D34: 17130 | E34: 14138 | F34: 14263 | G34: 15972 | H34: =G34*(1+H50) -> 16451.16 | I34: =H34*(1+I50) -> 16944.695 | J34: =I34*(1+J50) -> 17453.036 | K34: =J34*(1+K50) -> 17976.627 | L34: =K34*(1+L50) -> 18515.926
B35: Other Revenues | C35: 1022 | D35: 1118 | E35: 1179 | F35: 959 | G35: 1031 | H35: =G35*(1+H51) -> 1041.31 | I35: =H35*(1+I51) -> 1051.7231 | J35: =I35*(1+J51) -> 1062.2403 | K35: =J35*(1+K51) -> 1072.8627 | L35: =K35*(1+L51) -> 1083.5914
B36: Total Revenue | C36: =SUM(C33:C35) -> 80118 | D36: =SUM(D33:D35) -> 79571 | E36: =SUM(E33:E35) -> 78558 | F36: =SUM(F33:F35) -> 81400 | G36: =SUM(G33:G35) -> 88309 | H36: =SUM(H33:H35) -> 94468.04 | I36: =SUM(I33:I35) -> 100831.37 | J36: =SUM(J33:J35) -> 106683.51 | ... L36: =SUM(L33:L35) -> 118864.83
B38: Segmented Revenue Cases:
B39: Bear
B40: Base
B41: Bull
B43: Chosen Case:
B44: Base | C44: Historicals | H44: Expected
B45: Segmented Revenue YOY Growth (%) | C45: 2021A | D45: 2022A | E45: 2023A | F45: 2024A | G45: 2025A | H45: 2026E | I45: 2027E | J45: 2028E | K45: 2029E | L45: 2030E
...

Sheet Debt Schedule
B2: TMUS | C2: Historicals | D2: Projected
C3: 2025 | D3: 2026 | E3: 2027 | F3: 2028 | G3: 2029 | H3: 2030
B4: Short Term Debt:
B5: Revolver | D5: ='Balance Sheet'!H25 -> 0 | E5: ='Balance Sheet'!I25 -> 0 | F5: ='Balance Sheet'!J25 -> 0 | G5: ='Balance Sheet'!K25 -> 0 | H5: ='Balance Sheet'!L25 -> 0
B6: 1.500% Senior Notes due 2026
B7: Interest Rate | C7: 0.015 | D7: 0.015 | E7: 0 | F7: 0 | G7: 0 | H7: 0
B8: Ending Balance | C8: 1000 | D8: 0 | E8: 0 | F8: 0 | G8: 0 | H8: 0
B10: Average Balance | C10: =C8 -> 1000 | D10: =C10/2 -> 500 | E10: 0 | F10: 0 | G10: 0 | H10: 0
B11: Interest Expense | C11: =C10*C7 -> 15 | D11: =D10*D7 -> 7.5 | E11: 0 | F11: 0 | G11: 0 | H11: 0
B13: 2.250% Senior Notes due 2026
B14: Interest Rate | C14: 0.0225 | D14: 0.0225 | E14: 0 | F14: 0 | G14: 0 | H14: 0
B15: Ending Balance | C15: 1800 | D15: 0 | E15: 0 | F15: 0 | G15: 0 | H15: 0
B17: Average Balance | C17: =C15 -> 1800 | D17: =C17/2 -> 900 | E17: 0 | F17: 0 | G17: 0 | H17: 0
B18: Interest Expense | C18: =C17*C14 -> 40.5 | D18: =D17*D14 -> 20.25 | E18: 0 | F18: 0 | G18: 0 | H18: 0
B20: 2.625% Senior Notes due 2026
B21: Interest Rate | C21: 0.02625 | D21: 0.02625 | E21: 0 | F21: 0 | G21: 0 | H21: 0
B22: Ending Balance | C22: 1200 | D22: 0 | E22: 0 | F22: 0 | G22: 0 | H22: 0
B24: Average Balance | C24: =C22 -> 1200 | D24: =C22/2 -> 600 | E24: 0 | F24: =E24-E25 -> 0 | G24: =F24-F25 -> 0 | H24: =G24-G25 -> 0
B25: Interest Expense | C25: =C24*C21 -> 31.5 | D25: =D24*D21 -> 15.75 | E25: 0 | F25: 0 | G25: 0 | H25: 0
B27: Long Term Debt:
B29: 3.750% Senior Notes due 2027 | D29: =C32 -> 4000 | E29: =D32 -> 4000 | F29: 0 | G29: 0 | H29: 0
B31: Paydown | D31: =0 -> 0 | E31: =E29 -> 4000 | F31: 0 | G31: 0 | H31: 0
B32: Ending Balance | C32: 4000 | D32: =D29-D31 -> 4000 | E32: =E29-E31 -> 0 | F32: 0 | G32: 0 | H32: 0
B34: Interest Rate | C34: 0.0375 | D34: 0.0375 | E34: 0.0375 | F34: 0 | G34: 0 | H34: 0
B36: Average Balance | D36: =AVERAGE(D32,C32) -> 4000 | E36: =AVERAGE(E32,D32) -> 2000 | F36: 0 | G36: 0 | H36: 0
B37: Effective Interest Expense | D37: =D36*D34 -> 150 | E37: =E34*E36 -> 75 | F37: 0 | G37: 0 | H37: 0
B39: 2.050% Senior Notes due 2028 | D39: =C42 -> 1750 | E39: =D42 -> 1750 | F39: =E39 -> 1750 | G39: 0 | H39: 0
B41: Paydown | D41: =0 -> 0 | E41: 0 | F41: =F39 -> 1750 | G41: 0 | H41: 0
B42: Ending Balance | C42: 1750 | D42: =D39-D41 -> 1750 | E42: =E39-E41 -> 1750 | F42: =F39-F41 -> 0 | G42: 0 | H42: 0
B44: Interest Rate | C44: 0.0205 | D44: 0.0205 | E44: 0.0205 | F44: 0.0205 | G44: 0 | H44: 0
B46: Average Balance | D46: =AVERAGE(D42,C42) -> 1750 | E46: =AVERAGE(E42,D42) -> 1750 | F46: =AVERAGE(F42,E42) -> 875 | G46: 0 | H46: 0
B47: Effective Interest Expense | D47: =D46*D44 -> 35.875 | E47: =E44*E46 -> 35.875 | F47: =F44*F46 -> 17.9375 | G47: =G44*G46 -> 0 | H47: 0
B49: 4.750% Senior Notes due 2028 | D49: =C52 -> 1500 | E49: =D52 -> 1500 | F49: =E49 -> 1500 | G49: 0 | H49: 0
B51: Paydown | D51: =0 -> 0 | E51: 0 | F51: =F49 -> 1500 | G51: 0 | H51: 0
B52: Ending Balance | C52: 1500 | D52: =D49-D51 -> 1500 | E52: =E49-E51 -> 1500 | F52: =F49-F51 -> 0 | G52: 0 | H52: 0
B54: Interest Rate | C54: 0.0475 | D54: 0.0475 | E54: 0.0475 | F54: 0.0475 | G54: 0 | H54: 0
B56: Average Balance | D56: =AVERAGE(D52,C52) -> 1500 | E56: =AVERAGE(E52,D52) -> 1500 | F56: =AVERAGE(F52,E52) -> 750 | G56: 0 | H56: 0
B57: Effective Interest Expense | D57: =D56*D54 -> 71.25 | E57: =E54*E56 -> 71.25 | F57: =F54*F56 -> 35.625 | G57: =G54*G56 -> 0 | H57: 0
B59: 4.750% Senior Notes to affiliates due 2028 | D59: =C62 -> 1500 | E59: =D62 -> 1500 | F59: =E59 -> 1500 | G59: 0 | H59: 0
B61: Paydown | D61: =0 -> 0 | E61: 0 | F61: =F59 -> 1500 | G61: 0 | H61: 0
...

Sheet Balance Sheet
B2: T-Mobile US (TMUS) | C2: Historicals | H2: Projected
B3: $ in Millions | C3: 2021A | D3: 2022A | E3: 2023A | F3: 2024A | G3: 2025A | H3: 2026E | I3: 2027E | J3: 2028E | K3: 2029E | L3: 2030E
B4: Current assets
B5: Cash and cash equivalents | C5: 6631 | D5: 4507 | E5: 5135 | F5: 5409 | G5: 5598 | H5: =Assumptions!L14*'Income Statement'!H11 -> 5668.0824 | I5: =Assumptions!M14*'Income Statement'!I11 -> 5848.2196 | J5: =Assumptions!N14*'Income Statement'!J11 -> 6401.0104 | K5: =Assumptions!O14*'Income Statement'!K11 -> 6983.091 | L5: =Assumptions!P14*'Income Statement'!L11 -> 7369.6192
B6: Excess Cash /Revolver | H6: =IF('Cashflow Statement'!D96>0,'Cashflow Statement'!D96,0) -> 30959.54 | I6: =IF('Cashflow Statement'!E96>0,'Cashflow Statement'!E96,0) -> 53712.167 | J6: =IF('Cashflow Statement'!F96>0,'Cashflow Statement'!F96,0) -> 72350.044 | K6: =IF('Cashflow Statement'!G96>0,'Cashflow Statement'!G96,0) -> 97751.828 | L6: =IF('Cashflow Statement'!H96>0,'Cashflow Statement'!H96,0) -> 124463.01
B7: Accounts receivable | C7: 4194 | D7: 4445 | E7: 4692 | F7: 4276 | G7: 4874 | H7: =Assumptions!L15*'Income Statement'!H11 -> 5290.2102 | I7: =Assumptions!M15*'Income Statement'!I11 -> 5747.3882 | J7: =Assumptions!N15*'Income Statement'!J11 -> 5974.2764 | K7: =Assumptions!O15*'Income Statement'!K11 -> 6194.6775 | L7: =Assumptions!P15*'Income Statement'!L11 -> 6537.5654
B8: Equipment installment plan receivables, | C8: 4748 | D8: 5123 | E8: 4456 | F8: 4379 | G8: 4997 | H8: =Assumptions!L16*'Income Statement'!C11 -> 4646.844 | I8: =Assumptions!M16*'Income Statement'!D11 -> 4535.547 | J8: =Assumptions!N16*'Income Statement'!E11 -> 4242.132 | K8: =Assumptions!O16*'Income Statement'!F11 -> 4314.2 | L8: =Assumptions!P16*'Income Statement'!G11 -> 4768.686
B9: Inventory | C9: 2567 | D9: 1884 | E9: 1678 | F9: 1607 | G9: 2405 | H9: =('Income Statement'!H13+'Income Statement'!H14)*Assumptions!L17 -> 2373.5095 | I9: =('Income Statement'!I13+'Income Statement'!I14)*Assumptions!M17 -> 2455.4456 | J9: =('Income Statement'!J13+'Income Statement'!J14)*Assumptions!N17 -> 2440.3852 | K9: =('Income Statement'!K13+'Income Statement'!K14)*Assumptions!O17 -> 2486.8814 | L9: =('Income Statement'!L13+'Income Statement'!L14)*Assumptions!P17 -> 2545.728
B10: Prepaid expenses | C10: 746 | D10: 673 | E10: 702 | F10: 880 | G10: 1215 | H10: =Assumptions!L18*'Income Statement'!H11 -> 1180.8505 | I10: =Assumptions!M18*'Income Statement'!I11 -> 1109.1451 | J10: =Assumptions!N18*'Income Statement'!J11 -> 1066.8351 | K10: =Assumptions!O18*'Income Statement'!K11 -> 1069.9897 | L10: =Assumptions!P18*'Income Statement'!L11 -> 1129.2158
B11: Other current assets | C11: 2005 | D11: 2435 | E11: 2352 | F11: 1853 | G11: 5372 | H11: =Assumptions!L19*'Income Statement'!H11 -> 7557.4432 | I11: =Assumptions!M19*'Income Statement'!I11 -> 7058.196 | J11: =Assumptions!N19*'Income Statement'!J11 -> 6721.0609 | K11: =Assumptions!O19*'Income Statement'!K11 -> 5631.525 | L11: =Assumptions!P19*'Income Statement'!L11 -> 5705.5116
B12: Total current assets | C12: =C5+C7+C8+C9+C10+C11 -> 20891 | D12: =D5+D7+D8+D9+D10+D11 -> 19067 | E12: =E5+E7+E8+E9+E10+E11 -> 19015 | F12: =F5+F7+F8+F9+F10+F11 -> 18404 | G12: =G5+G7+G8+G9+G10+G11 -> 24461 | H12: =SUM(H5:H11) -> 57676.479 | I12: =SUM(I5:I11) -> 80466.108 | J12: =SUM(J5:J11) -> 99195.744 | K12: =SUM(K5:K11) -> 124432.19 | L12: =SUM(L5:L11) -> 152519.33
B14: Property and equipment, net | C14: 39803 | D14: 42086 | E14: 40432 | F14: 38533 | G14: 38333 | H14: =Calcs!H17 -> 32948.322 | I14: =Calcs!I17 -> 27906.753 | J14: =Calcs!J17 -> 22785.945 | K14: =Calcs!K17 -> 17379.681 | L14: =Calcs!L17 -> 11793.034
B15: Operating lease right-of-use assets | C15: 26959 | D15: 28715 | E15: 27135 | F15: 25398 | G15: 25692 | H15: =Assumptions!L22*'Income Statement'!H11 -> 26923.391 | I15: =Assumptions!M22*'Income Statement'!I11 -> 28031.121 | J15: =Assumptions!N22*'Income Statement'!J11 -> 29231.281 | K15: =Assumptions!O22*'Income Statement'!K11 -> 30410.235 | L15: =Assumptions!P22*'Income Statement'!L11 -> 32093.503
B16: Financing lease right-of-use assets | C16: 3322 | D16: 3257 | E16: 3270 | F16: 3091 | G16: 2760 | H16: =Assumptions!L23*'Income Statement'!H11 -> 2881.2752 | I16: =Assumptions!M23*'Income Statement'!I11 -> 3024.9411 | J16: =Assumptions!N23*'Income Statement'!J11 -> 3093.8217 | K16: =Assumptions!O23*'Income Statement'!K11 -> 3153.654 | L16: =Assumptions!P23*'Income Statement'!L11 -> 3268.7827
B17: Goodwill | C17: 12188 | D17: 12234 | E17: 12234 | F17: 13005 | G17: 13678 | H17: 13678 | I17: 13678 | J17: 13678 | K17: 13678 | L17: 13678
B18: Spectrum licenses | C18: 92606 | D18: 95798 | E18: 96707 | F18: 100558 | G18: 98032 | H18: 98032 | I18: 98032 | J18: 98032 | K18: 98032 | L18: 98032
B19: Other intangible assets, net | C19: 4733 | D19: 3508 | E19: 2618 | F19: 2512 | G19: 3843 | H19: =Assumptions!L26*'Income Statement'!H11 -> 3778.7216 | I19: =Assumptions!M26*'Income Statement'!I11 -> 3629.9294 | J19: =Assumptions!N26*'Income Statement'!J11 -> 3413.8722 | K19: =Assumptions!O26*'Income Statement'!K11 -> 3435.2302 | L19: =Assumptions!P26*'Income Statement'!L11 -> 3625.3772
B20: Equipment installment plan receivables | C20: 2829 | D20: 2546 | E20: 2042 | F20: 2209 | G20: 2683 | H20: =Assumptions!L27*'Income Statement'!H11 -> 2928.5092 | I20: =Assumptions!M27*'Income Statement'!I11 -> 3176.1882 | J20: =Assumptions!N27*'Income Statement'!J11 -> 3307.1887 | K20: =Assumptions!O27*'Income Statement'!K11 -> 3435.2302 | L20: =Assumptions!P27*'Income Statement'!L11 -> 3625.3772
B21: Other assets | C21: 3232 | D21: 4127 | E21: 4229 | F21: 4325 | G21: 9755 | H21: =Assumptions!L28*'Income Statement'!H11 -> 7557.4432 | I21: =Assumptions!M28*'Income Statement'!I11 -> 6049.8823 | J21: =Assumptions!N28*'Income Statement'!J11 -> 5867.5929 | K21: =Assumptions!O28*'Income Statement'!K11 -> 5631.525 | L21: =Assumptions!P28*'Income Statement'!L11 -> 5705.5116
B22: Total assets | C22: 206563 | D22: 211338 | E22: 207682 | F22: 208035 | G22: 219237 | H22: =SUM(H12:H21) -> 246404.14 | I22: =SUM(I12:I21) -> 263994.92 | J22: =SUM(J12:J21) -> 278605.44 | K22: =SUM(K12:K21) -> 299587.75 | L22: =SUM(L12:L21) -> 324340.92
B24: Current liabilities
B25: New Revolver | H25: =IF('Cashflow Statement'!D95<0,-'Cashflow Statement'!D95,0) -> 0 | I25: =IF('Cashflow Statement'!E95<0,-'Cashflow Statement'!E95,0) -> 0 | J25: =IF('Cashflow Statement'!F95<0,-'Cashflow Statement'!F95,0) -> 0 | K25: =IF('Cashflow Statement'!G95<0,-'Cashflow Statement'!G95,0) -> 0 | L25: =IF('Cashflow Statement'!H95<0,-'Cashflow Statement'!H95,0) -> 0
B26: Accounts payable and accrued liabilities | C26: 11405 | D26: 12275 | E26: 10373 | F26: 8463 | G26: 10280 | H26: =Assumptions!L30*('Income Statement'!H13+'Income Statement'!H14) -> 10733.931 | I26: =Assumptions!M30*('Income Statement'!I13+'Income Statement'!I14) -> 10435.644 | J26: =Assumptions!N30*('Income Statement'!J13+'Income Statement'!J14) -> 11841.869 | K26: =Assumptions!O30*('Income Statement'!K13+'Income Statement'!K14) -> 12765.991 | L26: =Assumptions!P30*('Income Statement'!L13+'Income Statement'!L14) -> 13462.155
B27: Short-term debt | C27: 3378 | D27: 5164 | E27: 3619 | F27: 4068 | G27: 5135 | H27: 5135 | I27: 5135 | J27: 5135 | K27: 5135 | L27: 5135
B28: Short Term debt to affiliates | C28: 2245 | D28: 0 | E28: 0 | F28: 0 | G28: 0
B29: Deferred revenue | C29: 856 | D29: 780 | E29: 825 | F29: 1222 | G29: 1533 | H29: =Assumptions!L31*'Income Statement'!H11 -> 1823.2332 | I29: =Assumptions!M31*'Income Statement'!I11 -> 2480.4517 | J29: =Assumptions!N31*'Income Statement'!J11 -> 2784.4395 | K29: =Assumptions!O31*'Income Statement'!K11 -> 3187.4431 | L29: =Assumptions!P31*'Income Statement'!L11 -> 3577.8312
B30: Short-term operating lease liabilities | C30: 3425 | D30: 3512 | E30: 3555 | F30: 3281 | G30: 3814 | H30: =Assumptions!L32*'Income Statement'!H11 -> 4203.8278 | I30: =Assumptions!M32*'Income Statement'!I11 -> 4285.3333 | J30: =Assumptions!N32*'Income Statement'!J11 -> 4470.0389 | K30: =Assumptions!O32*'Income Statement'!K11 -> 4820.5854 | L30: =Assumptions!P32*'Income Statement'!L11 -> 5134.9605
B31: Short-term financing lease liabilities | C31: 1120 | D31: 1161 | E31: 1260 | F31: 1175 | G31: 1163 | H31: =Assumptions!L33*'Income Statement'!H11 -> 1331.9994 | I31: =Assumptions!M33*'Income Statement'!I11 -> 1532.6368 | J31: =Assumptions!N33*'Income Statement'!J11 -> 1685.5994 | K31: =Assumptions!O33*'Income Statement'!K11 -> 1655.6683 | L31: =Assumptions!P33*'Income Statement'!L11 -> 1652.2211
B32: Other current liabilities | C32: 1070 | D32: 1850 | E32: 1296 | F32: 1965 | G32: 2575 | H32: =Assumptions!L34*'Income Statement'!H11 -> 2881.2752 | I32: =Assumptions!M34*'Income Statement'!I11 -> 3236.687 | J32: =Assumptions!N34*'Income Statement'!J11 -> 3360.5305 | K32: =Assumptions!O34*'Income Statement'!K11 -> 3705.5434 | L32: =Assumptions!P34*'Income Statement'!L11 -> 3958.1987
B33: Total current liabilities | C33: 23499 | D33: 24742 | E33: 20928 | F33: 20174 | G33: 24500 | H33: =SUM(H26:H32) -> 26109.267 | I33: =SUM(I26:I32) -> 27105.753 | J33: =SUM(J26:J32) -> 29277.478 | K33: =SUM(K26:K32) -> 31270.232 | L33: =SUM(L26:L32) -> 32920.366
B35: Long-term debt | C35: 67076 | D35: 66796 | E35: 71399 | F35: 74197
B36: Senior Notes due 2026 | G36: 1000 | H36: ='Debt Schedule'!D8 -> 0 | I36: ='Debt Schedule'!E8 -> 0 | J36: ='Debt Schedule'!F8 -> 0 | K36: ='Debt Schedule'!G8 -> 0 | L36: ='Debt Schedule'!H8 -> 0
B37: Senior Notes Due 2026 | G37: 1800 | H37: ='Debt Schedule'!D15 -> 0 | I37: ='Debt Schedule'!E15 -> 0 | J37: ='Debt Schedule'!F15 -> 0 | K37: ='Debt Schedule'!G15 -> 0 | L37: ='Debt Schedule'!H15 -> 0
B38: Senior Notes Due 2026 | G38: 1200 | H38: ='Debt Schedule'!D22 -> 0 | I38: ='Debt Schedule'!E22 -> 0 | J38: ='Debt Schedule'!F22 -> 0 | K38: ='Debt Schedule'!G22 -> 0 | L38: ='Debt Schedule'!H22 -> 0
B39: Senior Notes Due 2027 | G39: 4000 | H39: ='Debt Schedule'!D32 -> 4000 | I39: ='Debt Schedule'!E31 -> 4000 | J39: ='Debt Schedule'!F31 -> 0 | K39: ='Debt Schedule'!G31 -> 0 | L39: ='Debt Schedule'!H31 -> 0
B40: Senior Notes Due 2028 | G40: 1750 | H40: ='Debt Schedule'!D42 -> 1750 | I40: ='Debt Schedule'!E42 -> 1750 | J40: ='Debt Schedule'!F42 -> 0 | K40: ='Debt Schedule'!G42 -> 0 | L40: ='Debt Schedule'!H42 -> 0
B41: Senior Notes due 2028 | G41: 1500 | H41: ='Debt Schedule'!D52 -> 1500 | I41: ='Debt Schedule'!E52 -> 1500 | J41: ='Debt Schedule'!F52 -> 0 | K41: ='Debt Schedule'!G52 -> 0 | L41: ='Debt Schedule'!H52 -> 0
B42: Senior Notes to Affiliates due 2028 | G42: 1500 | H42: ='Debt Schedule'!D62 -> 1500 | I42: ='Debt Schedule'!E62 -> 1500 | J42: ='Debt Schedule'!F62 -> 0 | K42: ='Debt Schedule'!G62 -> 0 | L42: ='Debt Schedule'!H62 -> 0
B43: Senior Notes Due 2028 | G43: 900 | H43: ='Debt Schedule'!D72 -> 900 | I43: ='Debt Schedule'!E72 -> 900 | J43: ='Debt Schedule'!F72 -> 0 | K43: ='Debt Schedule'!G72 -> 0 | L43: ='Debt Schedule'!H72 -> 0
B44: Senior Notes due 2028 | G44: 1000 | H44: ='Debt Schedule'!D82 -> 1000 | I44: ='Debt Schedule'!E82 -> 1000 | J44: ='Debt Schedule'!F82 -> 0 | K44: ='Debt Schedule'!G82 -> 0 | L44: ='Debt Schedule'!H82 -> 0
...

Sheet Cashflow Statement
B2: Consolidated Statements of Cash Flows - USD ($) | C2: Historical | D2: Projected
B3: In Millions | C3: 2025A | D3: 2026E | E3: 2027E | F3: 2028E | G3: 2029E | H3: 2030E
B4: Operating activities
B5: Net income | C5: ='Income Statement'!G25 -> 10992 | D5: {='Income Statement'!H25:L25} -> 14205.544 | E5: 13318.179 | F5: 17174.899 | G5: 19844.48 | H5: 22347.926
B6: Depreciation and amortization | C6: =Calcs!G16 -> 13508 | D6: =Calcs!H16 -> 15965.099 | E6: =Calcs!I16 -> 16233.851 | F6: =Calcs!J16 -> 16749.311 | G6: =Calcs!K16 -> 17570.358 | H6: =Calcs!L16 -> 18305.183
B7: Changes in Working Capital | C7: =Calcs!G38 -> -2609 | D7: =Calcs!H38 -> -576.59086 | E7: =Calcs!I38 -> 1139.6216 | F7: =Calcs!J38 -> 2632.7573 | G7: =Calcs!K38 -> 2740.17 | H7: =Calcs!L38 -> 660.70129
B8: Cash Flow from Operations | C8: =SUM(C5:C7) -> 21891 | D8: =SUM(D5:D7) -> 29594.052 | E8: =SUM(E5:E7) -> 30691.651 | F8: =SUM(F5:F7) -> 36556.967 | G8: =SUM(G5:G7) -> 40155.008 | H8: =SUM(H5:H7) -> 41313.81
B10: Investing Activities
B11: Capital Expenditures | C11: =Calcs!G15 -> -9955 | D11: =Calcs!H15 -> -10580.42 | E11: =Calcs!I15 -> -11192.282 | F11: =Calcs!J15 -> -11628.502 | G11: =Calcs!K15 -> -12164.094 | H11: =Calcs!L15 -> -12718.536
B12: Changes in Non-Working Capital | C12: =Calcs!G60 -> -2881 | D12: =Calcs!H60 -> 9881.9907 | E12: =Calcs!I60 -> 3433.3958 | F12: =Calcs!J60 -> 8214.2027 | G12: =Calcs!K60 -> 5747.9516 | H12: =Calcs!L60 -> 6002.4341
B13: Cash Flow from Investing | C13: =SUM(C11:C12) -> -12836 | D13: =SUM(D11:D12) -> -698.42981 | E13: =SUM(E11:E12) -> -7758.8865 | F13: =SUM(F11:F12) -> -3414.2996 | G13: =SUM(G11:G12) -> -6416.1423 | H13: =SUM(H11:H12) -> -6716.1022
B15: Financing activities
B16: Senior Notes Due 2026 | D16: ='Balance Sheet'!H36-'Balance Sheet'!G36 -> -1000 | E16: ='Balance Sheet'!I36-'Balance Sheet'!H36 -> 0 | F16: ='Balance Sheet'!J36-'Balance Sheet'!I36 -> 0 | G16: ='Balance Sheet'!K36-'Balance Sheet'!J36 -> 0 | H16: ='Balance Sheet'!L36-'Balance Sheet'!K36 -> 0
B17: Senior Notes Due 2026 | D17: ='Balance Sheet'!H37-'Balance Sheet'!G37 -> -1800 | E17: ='Balance Sheet'!I37-'Balance Sheet'!H37 -> 0 | F17: ='Balance Sheet'!J37-'Balance Sheet'!I37 -> 0 | G17: ='Balance Sheet'!K37-'Balance Sheet'!J37 -> 0 | H17: ='Balance Sheet'!L37-'Balance Sheet'!K37 -> 0
B18: Senior Notes Due 2026 | D18: ='Balance Sheet'!H38-'Balance Sheet'!G38 -> -1200 | E18: ='Balance Sheet'!I38-'Balance Sheet'!H38 -> 0 | F18: ='Balance Sheet'!J38-'Balance Sheet'!I38 -> 0 | G18: ='Balance Sheet'!K38-'Balance Sheet'!J38 -> 0 | H18: ='Balance Sheet'!L38-'Balance Sheet'!K38 -> 0
B19: Senior Notes Due 2027 | D19: ='Balance Sheet'!H39-'Balance Sheet'!G39 -> 0 | E19: ='Balance Sheet'!I39-'Balance Sheet'!H39 -> 0 | F19: ='Balance Sheet'!J39-'Balance Sheet'!I39 -> -4000 | G19: ='Balance Sheet'!K39-'Balance Sheet'!J39 -> 0 | H19: ='Balance Sheet'!L39-'Balance Sheet'!K39 -> 0
B20: Senior Notes Due 2028 | D20: ='Balance Sheet'!H40-'Balance Sheet'!G40 -> 0 | E20: ='Balance Sheet'!I40-'Balance Sheet'!H40 -> 0 | F20: ='Balance Sheet'!J40-'Balance Sheet'!I40 -> -1750 | G20: ='Balance Sheet'!K40-'Balance Sheet'!J40 -> 0 | H20: ='Balance Sheet'!L40-'Balance Sheet'!K40 -> 0
B21: Senior Notes due 2028 | D21: ='Balance Sheet'!H41-'Balance Sheet'!G41 -> 0 | E21: ='Balance Sheet'!I41-'Balance Sheet'!H41 -> 0 | F21: ='Balance Sheet'!J41-'Balance Sheet'!I41 -> -1500 | G21: ='Balance Sheet'!K41-'Balance Sheet'!J41 -> 0 | H21: ='Balance Sheet'!L41-'Balance Sheet'!K41 -> 0
B22: Senior Notes to Affiliates due 2028 | D22: ='Balance Sheet'!H42-'Balance Sheet'!G42 -> 0 | E22: ='Balance Sheet'!I42-'Balance Sheet'!H42 -> 0 | F22: ='Balance Sheet'!J42-'Balance Sheet'!I42 -> -1500 | G22: ='Balance Sheet'!K42-'Balance Sheet'!J42 -> 0 | H22: ='Balance Sheet'!L42-'Balance Sheet'!K42 -> 0
B23: Senior Notes Due 2028 | D23: ='Balance Sheet'!H43-'Balance Sheet'!G43 -> 0 | E23: ='Balance Sheet'!I43-'Balance Sheet'!H43 -> 0 | F23: ='Balance Sheet'!J43-'Balance Sheet'!I43 -> -900 | G23: ='Balance Sheet'!K43-'Balance Sheet'!J43 -> 0 | H23: ='Balance Sheet'!L43-'Balance Sheet'!K43 -> 0
B24: Senior Notes due 2028 | D24: ='Balance Sheet'!H44-'Balance Sheet'!G44 -> 0 | E24: ='Balance Sheet'!I44-'Balance Sheet'!H44 -> 0 | F24: ='Balance Sheet'!J44-'Balance Sheet'!I44 -> -1000 | G24: ='Balance Sheet'!K44-'Balance Sheet'!J44 -> 0 | H24: ='Balance Sheet'!L44-'Balance Sheet'!K44 -> 0
B25: Series 2018-1-A-2 Notes due 2028 | D25: ='Balance Sheet'!H45-'Balance Sheet'!G45 -> 0 | E25: ='Balance Sheet'!I45-'Balance Sheet'!H45 -> 0 | F25: ='Balance Sheet'!J45-'Balance Sheet'!I45 -> -827 | G25: ='Balance Sheet'!K45-'Balance Sheet'!J45 -> 0 | H25: ='Balance Sheet'!L45-'Balance Sheet'!K45 -> 0
B26: Senior Notes due 2028 | D26: ='Balance Sheet'!H46-'Balance Sheet'!G46 -> 0 | E26: ='Balance Sheet'!I46-'Balance Sheet'!H46 -> 0 | F26: ='Balance Sheet'!J46-'Balance Sheet'!I46 -> -2475 | G26: ='Balance Sheet'!K46-'Balance Sheet'!J46 -> 0 | H26: ='Balance Sheet'!L46-'Balance Sheet'!K46 -> 0
B27: Senior Notes Due 2029 | D27: ='Balance Sheet'!H47-'Balance Sheet'!G47 -> 0 | E27: ='Balance Sheet'!I47-'Balance Sheet'!H47 -> 0 | F27: ='Balance Sheet'!J47-'Balance Sheet'!I47 -> 0 | G27: ='Balance Sheet'!K47-'Balance Sheet'!J47 -> -500 | H27: ='Balance Sheet'!L47-'Balance Sheet'!K47 -> 0
... B80: Debt issuance costs and consent fees | D80: ='Balance Sheet'!H100-'Balance Sheet'!G100 -> 352 | E80: ='Balance Sheet'!I100-'Balance Sheet'!H100 -> 0 | F80: ='Balance Sheet'!J100-'Balance Sheet'!I100 -> 0 | G80: ='Balance Sheet'!K100-'Balance Sheet'!J100 -> 0 | H80: ='Balance Sheet'!L100-'Balance Sheet'!K100 -> 0
B81: Less:Current portion of senior notes | D81: ='Balance Sheet'!H107-'Balance Sheet'!G107 -> 5135 | E81: ='Balance Sheet'!I107-'Balance Sheet'!H107 -> 0 | F81: ='Balance Sheet'!J107-'Balance Sheet'!I107 -> 0 | G81: ='Balance Sheet'!K107-'Balance Sheet'!J107 -> 0 | H81: ='Balance Sheet'!L107-'Balance Sheet'!K107 -> 0
B82: Affiliated Debt | C82: 13
B83: Dividends | C83: -4121 | D83: =Calcs!H9 -> 0 | E83: =Calcs!I9 -> 0 | F83: =Calcs!J9 -> 0 | G83: =Calcs!K9 -> 0 | H83: =Calcs!L9 -> 0
B84: Total Cash from Financing | C84: =SUM(C82:C83) -> -4108 | D84: =SUM(D16:D83) -> 2134 | E84: =SUM(E16:E83) -> 0 | F84: =SUM(F16:F83) -> -13952 | G84: =SUM(G16:G83) -> -7755 | H84: =SUM(H16:H83) -> -7500
B88: Net Change In Cash | C88: =SUM(C8,C13,C84) -> 4947 | D88: =SUM(D8,D13,D84) -> 31029.622 | E88: =SUM(E8,E13,E84) -> 22932.765 | F88: =SUM(F8,F13,F84) -> 19190.667 | G88: =SUM(G8,G13,G84) -> 25983.865 | H88: =SUM(H8,H13,H84) -> 27097.708
B90: Cash Analysis
B91: Beginning Cash | D91: =C93 -> 5598 | E91: =D93 -> 36627.622 | F91: =E93 -> 59560.387 | G91: =F93 -> 78751.054 | H91: =G93 -> 104734.92
B92: Change in Cash from Cashflow Statement | D92: =D88 -> 31029.622 | E92: =E88 -> 22932.765 | F92: =F88 -> 19190.667 | G92: =G88 -> 25983.865 | H92: =H88 -> 27097.708
B93: Net Cash Available at the End of the Year | C93: ='Balance Sheet'!G5 -> 5598 | D93: =SUM(D91:D92) -> 36627.622 | E93: =SUM(E91:E92) -> 59560.387 | F93: =SUM(F91:F92) -> 78751.054 | G93: =SUM(G91:G92) -> 104734.92 | H93: =SUM(H91:H92) -> 131832.63
B95: Required Cash | C95: ='Debt Schedule'!C638 -> 5598 | D95: ='Debt Schedule'!D638 -> 5668.0824 | E95: ='Debt Schedule'!E638 -> 5848.2196 | F95: ='Debt Schedule'!F638 -> 6401.0104 | G95: ='Debt Schedule'!G638 -> 6983.091 | H95: ='Debt Schedule'!H638 -> 7369.6192
B96: Excess Cash/ Revolver | D96: =D93-D95 -> 30959.54 | E96: =E93-E95 -> 53712.167 | F96: =F93-F95 -> 72350.044 | G96: =G93-G95 -> 97751.828 | H96: =H93-H95 -> 124463.01

Sheet Calcs
B2: T-Mobile US INC. (TMUS) | C2: Historicals | H2: Expected
B3: $ in Millions | C3: 2021 | D3: 2022A | E3: 2023A | F3: 2024A | G3: 2025A | H3: 2026A | I3: 2027E | J3: 2028E | K3: 2029E | L3: 2030E
B5: Retained Earnings
D6: =C10 -> -2812 | E6: =D10 -> -223 | F6: =E10 -> 7347 | G6: =F10 -> 14384 | H6: =G10 -> 21136 | I6: =H10 -> 35341.544 | J6: =I10 -> 48659.723 | K6: =J10 -> 65834.622 | L6: =K10 -> 85679.101
B7: Net Income | D7: ='Income Statement'!D25 -> 2590 | E7: ='Income Statement'!E25 -> 8317 | F7: ='Income Statement'!F25 -> 11339 | G7: ='Income Statement'!G25 -> 10992 | H7: ='Income Statement'!H25 -> 14205.544 | I7: ='Income Statement'!I25 -> 13318.179 | J7: ='Income Statement'!J25 -> 17174.899 | K7: ='Income Statement'!K25 -> 19844.48 | L7: ='Income Statement'!L25 -> 22347.926
B8: Other Net | D8: -1 | E8: 0 | F8: 0 | G8: 0 | H8: 0 | I8: 0 | J8: 0 | K8: 0 | L8: 0
B9: Dividends | D9: 0 | E9: -747 | F9: -4302 | G9: -4240 | H9: 0 | I9: 0 | J9: 0 | K9: 0 | L9: 0
B10: Ending Balance | C10: ='Balance Sheet'!C115 -> -2812 | D10: =SUM(D6:D9) -> -223 | E10: =SUM(E6:E9) -> 7347 | F10: =SUM(F6:F9) -> 14384 | G10: =SUM(G6:G9) -> 21136 | H10: =SUM(H6:H9) -> 35341.544 | I10: =SUM(I6:I9) -> 48659.723 | J10: =SUM(J6:J9) -> 65834.622 | K10: =SUM(K6:K9) -> 85679.101 | L10: =SUM(L6:L9) -> 108027.03
B11: check | C11: ='Balance Sheet'!C115 -> -2812 | D11: ='Balance Sheet'!D115 -> -223 | E11: ='Balance Sheet'!E115 -> 7347 | F11: ='Balance Sheet'!F115 -> 14384 | G11: ='Balance Sheet'!G115 -> 21136 | H11: ='Balance Sheet'!H115 -> 35341.544 | I11: ='Balance Sheet'!I115 -> 48659.723 | J11: ='Balance Sheet'!J115 -> 65834.622 | ... L11: ='Balance Sheet'!L115 -> 108027.03
B13: PP&E (Property, Plant, and Equipment)
B14: Beginning Balance (Previous Ending) | D14: =C17 -> 39803 | E14: =D17 -> 42086 | F14: =E17 -> 40432 | G14: =F17 -> 38533 | H14: =G17 -> 38333 | I14: =H17 -> 32948.322 | J14: =I17 -> 27906.753 | K14: =J17 -> 22785.945 | L14: =K17 -> 17379.681
B15: Capital Expenditures (from CFS) | C15: -12326 | D15: -13970 | E15: -9801 | F15: -8840 | G15: -9955 | H15: =Assumptions!L49*'Income Statement'!H11 -> -10580.42 | I15: =Assumptions!M49*'Income Statement'!I11 -> -11192.282 | J15: =Assumptions!N49*'Income Statement'!J11 -> -11628.502 | K15: =Assumptions!O49*'Income Statement'!K11 -> -12164.094 | L15: =Assumptions!P49*'Income Statement'!L11 -> -12718.536
B16: Depreciation and Amortization | C16: ='Income Statement'!C18 -> 16383 | D16: ='Income Statement'!D18 -> 13651 | E16: ='Income Statement'!E18 -> 12818 | F16: ='Income Statement'!F18 -> 12919 | G16: ='Income Statement'!G18 -> 13508 | H16: ='Income Statement'!H18 -> 15965.099 | I16: ='Income Statement'!I18 -> 16233.851 | J16: ='Income Statement'!J18 -> 16749.311 | ... L16: ='Income Statement'!L18 -> 18305.183
B17: Ending Balance (from B/S) | C17: ='Balance Sheet'!C14 -> 39803 | D17: ='Balance Sheet'!D14 -> 42086 | E17: ='Balance Sheet'!E14 -> 40432 | F17: ='Balance Sheet'!F14 -> 38533 | G17: ='Balance Sheet'!G14 -> 38333 | H17: =H14-H15-H16 -> 32948.322 | I17: =I14-I15-I16 -> 27906.753 | J17: =J14-J15-J16 -> 22785.945 | K17: =K14-K15-K16 -> 17379.681 | L17: =L14-L15-L16 -> 11793.034
B19: Changes in Working Capital
B20: Current Assets:
B21: Accounts receivable | C21: ='Balance Sheet'!C7 -> 4194 | D21: ='Balance Sheet'!D7 -> 4445 | E21: ='Balance Sheet'!E7 -> 4692 | F21: ='Balance Sheet'!F7 -> 4276 | G21: ='Balance Sheet'!G7 -> 4874 | H21: ='Balance Sheet'!H7 -> 5290.2102 | I21: ='Balance Sheet'!I7 -> 5747.3882 | J21: ='Balance Sheet'!J7 -> 5974.2764 | ... L21: ='Balance Sheet'!L7 -> 6537.5654
B22: Equipment installment plan receivables, | C22: ='Balance Sheet'!C8 -> 4748 | D22: ='Balance Sheet'!D8 -> 5123 | E22: ='Balance Sheet'!E8 -> 4456 | F22: ='Balance Sheet'!F8 -> 4379 | G22: ='Balance Sheet'!G8 -> 4997 | H22: ='Balance Sheet'!H8 -> 4646.844 | I22: ='Balance Sheet'!I8 -> 4535.547 | J22: ='Balance Sheet'!J8 -> 4242.132 | ... L22: ='Balance Sheet'!L8 -> 4768.686
B23: Inventory | C23: ='Balance Sheet'!C9 -> 2567 | D23: ='Balance Sheet'!D9 -> 1884 | E23: ='Balance Sheet'!E9 -> 1678 | F23: ='Balance Sheet'!F9 -> 1607 | G23: ='Balance Sheet'!G9 -> 2405 | H23: =('Income Statement'!H13+'Income Statement'!H14)*Assumptions!L17 -> 2373.5095 | I23: =('Income Statement'!I13+'Income Statement'!I14)*Assumptions!M17 -> 2455.4456 | J23: =('Income Statement'!J13+'Income Statement'!J14)*Assumptions!N17 -> 2440.3852 | K23: =('Income Statement'!K13+'Income Statement'!K14)*Assumptions!O17 -> 2486.8814 | L23: =('Income Statement'!L13+'Income Statement'!L14)*Assumptions!P17 -> 2545.728
B24: Prepaid expenses | C24: ='Balance Sheet'!C10 -> 746 | D24: ='Balance Sheet'!D10 -> 673 | E24: ='Balance Sheet'!E10 -> 702 | F24: ='Balance Sheet'!F10 -> 880 | G24: ='Balance Sheet'!G10 -> 1215 | H24: ='Balance Sheet'!H10 -> 1180.8505 | I24: ='Balance Sheet'!I10 -> 1109.1451 | J24: ='Balance Sheet'!J10 -> 1066.8351 | ... L24: ='Balance Sheet'!L10 -> 1129.2158
B25: Other current assets | C25: ='Balance Sheet'!C11 -> 2005 | D25: ='Balance Sheet'!D11 -> 2435 | E25: ='Balance Sheet'!E11 -> 2352 | F25: ='Balance Sheet'!F11 -> 1853 | G25: ='Balance Sheet'!G11 -> 5372 | H25: ='Balance Sheet'!H11 -> 7557.4432 | I25: ='Balance Sheet'!I11 -> 7058.196 | J25: ='Balance Sheet'!J11 -> 6721.0609 | ... L25: ='Balance Sheet'!L11 -> 5705.5116
B26: Total Current Assets | C26: =SUM(C21:C25) -> 14260 | D26: =SUM(D21:D25) -> 14560 | E26: =SUM(E21:E25) -> 13880 | F26: =SUM(F21:F25) -> 12995 | G26: =SUM(G21:G25) -> 18863 | H26: =SUM(H21:H25) -> 21048.857 | I26: =SUM(I21:I25) -> 20905.722 | J26: =SUM(J21:J25) -> 20444.69 | ... L26: =SUM(L21:L25) -> 20686.707
B28: Current Liabilities:
B29: Accounts payable and accrued liabilities | C29: ='Balance Sheet'!C26 -> 11405 | D29: ='Balance Sheet'!D26 -> 12275 | E29: ='Balance Sheet'!E26 -> 10373 | F29: ='Balance Sheet'!F26 -> 8463 | G29: ='Balance Sheet'!G26 -> 10280 | H29: ='Balance Sheet'!H26 -> 10733.931 | I29: ='Balance Sheet'!I26 -> 10435.644 | J29: ='Balance Sheet'!J26 -> 11841.869 | ... L29: ='Balance Sheet'!L26 -> 13462.155
B30: Deferred revenue | C30: ='Balance Sheet'!C29 -> 856 | D30: ='Balance Sheet'!D29 -> 780 | E30: ='Balance Sheet'!E29 -> 825 | F30: ='Balance Sheet'!F29 -> 1222 | G30: ='Balance Sheet'!G29 -> 1533 | H30: ='Balance Sheet'!H29 -> 1823.2332 | I30: ='Balance Sheet'!I29 -> 2480.4517 | J30: ='Balance Sheet'!J29 -> 2784.4395 | ... L30: ='Balance Sheet'!L29 -> 3577.8312
B31: Short-term operating lease liabilities | C31: ='Balance Sheet'!C30 -> 3425 | D31: ='Balance Sheet'!D30 -> 3512 | E31: ='Balance Sheet'!E30 -> 3555 | F31: ='Balance Sheet'!F30 -> 3281 | G31: ='Balance Sheet'!G30 -> 3814 | H31: ='Balance Sheet'!H30 -> 4203.8278 | I31: ='Balance Sheet'!I30 -> 4285.3333 | J31: ='Balance Sheet'!J30 -> 4470.0389 | ... L31: ='Balance Sheet'!L30 -> 5134.9605
B32: Short-term financing lease liabilities | C32: ='Balance Sheet'!C31 -> 1120 | D32: ='Balance Sheet'!D31 -> 1161 | E32: ='Balance Sheet'!E31 -> 1260 | F32: ='Balance Sheet'!F31 -> 1175 | G32: ='Balance Sheet'!G31 -> 1163 | H32: ='Balance Sheet'!H31 -> 1331.9994 | I32: ='Balance Sheet'!I31 -> 1532.6368 | J32: ='Balance Sheet'!J31 -> 1685.5994 | ... L32: ='Balance Sheet'!L31 -> 1652.2211
B33: Other current liabilities | C33: ='Balance Sheet'!C32 -> 1070 | D33: ='Balance Sheet'!D32 -> 1850 | E33: ='Balance Sheet'!E32 -> 1296 | F33: ='Balance Sheet'!F32 -> 1965 | G33: ='Balance Sheet'!G32 -> 2575 | H33: ='Balance Sheet'!H32 -> 2881.2752 | I33: ='Balance Sheet'!I32 -> 3236.687 | J33: ='Balance Sheet'!J32 -> 3360.5305 | ... L33: ='Balance Sheet'!L32 -> 3958.1987
B34: Total Operating Liabilities | C34: =SUM(C29:C33) -> 17876 | D34: =SUM(D29:D33) -> 19578 | E34: =SUM(E29:E33) -> 17309 | F34: =SUM(F29:F33) -> 16106 | G34: =SUM(G29:G33) -> 19365 | H34: =SUM(H29:H33) -> 20974.267 | I34: =SUM(I29:I33) -> 21970.753 | J34: =SUM(J29:J33) -> 24142.478 | ... L34: =SUM(L29:L33) -> 27785.366
B36: Changes in Operating Assets (Cash Flow) | C36: =-(C26-23885) -> 9625 | D36: =-(D26-C26) -> -300 | E36: =-(E26-D26) -> 680 | F36: =-(F26-E26) -> 885 | G36: =-(G26-F26) -> -5868 | H36: =-(H26-G26) -> -2185.8574 | I36: =-(I26-H26) -> 143.13561 | J36: =-(J26-I26) -> 461.03221 | K36: =-(K26-J26) -> 747.41602 | L36: =-(L26-K26) -> -989.4332
B37: Changes in Operating Liabilties (Cash Flow) | C37: =C34-21703 -> -3827 | D37: =D34-C34 -> 1702 | E37: =E34-D34 -> -2269 | F37: =F34-E34 -> -1203 | G37: =G34-F34 -> 3259 | H37: =H34-G34 -> 1609.2666 | I37: =I34-H34 -> 996.48596 | J37: =J34-I34 -> 2171.7251 | K37: =K34-J34 -> 1992.754 | L37: =L34-K34 -> 1650.1345
B38: Changes in Operating Working Capital | C38: =SUM(C36:C37) -> 5798 | D38: =SUM(D36:D37) -> 1402 | E38: =SUM(E36:E37) -> -1589 | F38: =SUM(F36:F37) -> -318 | G38: =SUM(G36:G37) -> -2609 | H38: =SUM(H36:H37) -> -576.59086 | I38: =SUM(I36:I37) -> 1139.6216 | J38: =SUM(J36:J37) -> 2632.7573 | ... L38: =SUM(L36:L37) -> 660.70129
B40: Changes in Non-Working Capital:
B41: Operating lease right-of-use assets | C41: ='Balance Sheet'!C15 -> 26959 | D41: ='Balance Sheet'!D15 -> 28715 | E41: ='Balance Sheet'!E15 -> 27135 | F41: ='Balance Sheet'!F15 -> 25398 | G41: ='Balance Sheet'!G15 -> 25692 | H41: ='Balance Sheet'!H15 -> 26923.391 | I41: ='Balance Sheet'!I15 -> 28031.121 | J41: ='Balance Sheet'!J15 -> 29231.281 | ... L41: ='Balance Sheet'!L15 -> 32093.503
B42: Financing lease right-of-use assets | C42: ='Balance Sheet'!C16 -> 3322 | D42: ='Balance Sheet'!D16 -> 3257 | E42: ='Balance Sheet'!E16 -> 3270 | F42: ='Balance Sheet'!F16 -> 3091 | G42: ='Balance Sheet'!G16 -> 2760 | H42: ='Balance Sheet'!H16 -> 2881.2752 | I42: ='Balance Sheet'!I16 -> 3024.9411 | J42: ='Balance Sheet'!J16 -> 3093.8217 | ... L42: ='Balance Sheet'!L16 -> 3268.7827
B43: Goodwill | C43: ='Balance Sheet'!C17 -> 12188 | D43: ='Balance Sheet'!D17 -> 12234 | E43: ='Balance Sheet'!E17 -> 12234 | F43: ='Balance Sheet'!F17 -> 13005 | G43: ='Balance Sheet'!G17 -> 13678 | H43: ='Balance Sheet'!H17 -> 13678 | I43: ='Balance Sheet'!I17 -> 13678 | J43: ='Balance Sheet'!J17 -> 13678 | ... L43: ='Balance Sheet'!L17 -> 13678
B44: Spectrum licenses | C44: ='Balance Sheet'!C18 -> 92606 | D44: ='Balance Sheet'!D18 -> 95798 | E44: ='Balance Sheet'!E18 -> 96707 | F44: ='Balance Sheet'!F18 -> 100558 | G44: ='Balance Sheet'!G18 -> 98032 | H44: ='Balance Sheet'!H18 -> 98032 | I44: ='Balance Sheet'!I18 -> 98032 | J44: ='Balance Sheet'!J18 -> 98032 | ... L44: ='Balance Sheet'!L18 -> 98032
B45: Other intangible assets, net | C45: ='Balance Sheet'!C19 -> 4733 | D45: ='Balance Sheet'!D19 -> 3508 | E45: ='Balance Sheet'!E19 -> 2618 | F45: ='Balance Sheet'!F19 -> 2512 | G45: ='Balance Sheet'!G19 -> 3843 | H45: ='Balance Sheet'!H19 -> 3778.7216 | I45: ='Balance Sheet'!I19 -> 3629.9294 | J45: ='Balance Sheet'!J19 -> 3413.8722 | ... L45: ='Balance Sheet'!L19 -> 3625.3772
B46: Equipment installment plan receivables | C46: ='Balance Sheet'!C20 -> 2829 | D46: ='Balance Sheet'!D20 -> 2546 | E46: ='Balance Sheet'!E20 -> 2042 | F46: ='Balance Sheet'!F20 -> 2209 | G46: ='Balance Sheet'!G20 -> 2683 | H46: ='Balance Sheet'!H20 -> 2928.5092 | I46: ='Balance Sheet'!I20 -> 3176.1882 | J46: ='Balance Sheet'!J20 -> 3307.1887 | ... L46: ='Balance Sheet'!L20 -> 3625.3772
B47: Other assets | C47: ='Balance Sheet'!C21 -> 3232 | D47: ='Balance Sheet'!D21 -> 4127 | E47: ='Balance Sheet'!E21 -> 4229 | F47: ='Balance Sheet'!F21 -> 4325 | G47: ='Balance Sheet'!G21 -> 9755 | H47: ='Balance Sheet'!H21 -> 7557.4432 | I47: ='Balance Sheet'!I21 -> 6049.8823 | J47: ='Balance Sheet'!J21 -> 5867.5929 | ... L47: ='Balance Sheet'!L21 -> 5705.5116
...

Sheet Assumptions
B2: TMUS Assumptions | C2: Historicals | I2: Average | L2: Projected
C3: 2021A | D3: 2022A | E3: 2023A | F3: 2024A | G3: 2025A | I3: 5 YR AVG | J3: 3 YR AVG | L3: 2026E | M3: 2027E | N3: 2028E | O3: 2029E | P3: 2030E
B4: Income Statement:
B5: Total Service Revenues | D5: =('Income Statement'!D8-'Income Statement'!C8)/'Income Statement'!C8 -> 0.050609056 | E5: =('Income Statement'!E8-'Income Statement'!D8)/'Income Statement'!D8 -> 0.031277009 | F5: =('Income Statement'!F8-'Income Statement'!E8)/'Income Statement'!E8 -> 0.046441391 | G5: =('Income Statement'!G8-'Income Statement'!F8)/'Income Statement'!F8 -> 0.077487987 | I5: =AVERAGE(C5:G5) -> 0.051453861 | J5: =AVERAGE(E5:G5) -> 0.051735462 | L5: ='Income Statement'!H49 -> 0.07951042 | M5: ='Income Statement'!I49 -> 0.076120043 | N5: ='Income Statement'!J49 -> 0.064384383 | O5: ='Income Statement'!K49 -> 0.061391488 | P5: ='Income Statement'!L49 -> 0.060742008
B6: Total Revenues | D6: =('Income Statement'!D11-'Income Statement'!C11)/'Income Statement'!C11 -> -0.0068274295 | E6: =('Income Statement'!E11-'Income Statement'!D11)/'Income Statement'!D11 -> -0.012730769 | F6: =('Income Statement'!F11-'Income Statement'!E11)/'Income Statement'!E11 -> 0.036177092 | G6: =('Income Statement'!G11-'Income Statement'!F11)/'Income Statement'!F11 -> 0.08487715 | I6: =AVERAGE(C6:G6) -> 0.025374011 | J6: =AVERAGE(E6:G6) -> 0.036107824 | L6: ='Income Statement'!H52 -> 0.069744194 | M6: ='Income Statement'!I52 -> 0.067359623 | N6: ='Income Statement'!J52 -> 0.058038836 | O6: ='Income Statement'!K52 -> 0.055744253 | P6: ='Income Statement'!L52 -> 0.055352022
B7: Cost of Services, excluding Depreciation and Amortization | C7: ='Income Statement'!C13/'Income Statement'!C11 -> 0.17391847 | D7: ='Income Statement'!D13/'Income Statement'!D11 -> 0.18431338 | E7: ='Income Statement'!E13/'Income Statement'!E11 -> 0.14836172 | F7: ='Income Statement'!F13/'Income Statement'!F11 -> 0.13232187 | G7: ='Income Statement'!G13/'Income Statement'!G11 -> 0.13019058 | I7: =AVERAGE(C7:G7) -> 0.1538212 | J7: =AVERAGE(E7:G7) -> 0.13695806 | L7: 0.127 | M7: 0.128 | N7: 0.125 | O7: 0.123 | P7: 0.1215
B8: Cost of Equipment Sales | C8: ='Income Statement'!C14/'Income Statement'!C11 -> 0.28297012 | D8: ='Income Statement'!D14/'Income Statement'!D11 -> 0.27070164 | E8: ='Income Statement'!E14/'Income Statement'!E11 -> 0.23591487 | F8: ='Income Statement'!F14/'Income Statement'!F11 -> 0.2319656 | G8: ='Income Statement'!G14/'Income Statement'!G11 -> 0.24093807 | I8: =AVERAGE(C8:G8) -> 0.25249806 | J8: =AVERAGE(E8:G8) -> 0.23627285 | L8: 0.248 | M8: 0.2525 | N8: 0.25 | O8: 0.245 | P8: 0.2415
B9: Selling, General and Administrative | C9: ='Income Statement'!C15/'Income Statement'!C11 -> 0.25260241 | D9: ='Income Statement'!D15/'Income Statement'!D11 -> 0.27154365 | E9: ='Income Statement'!E15/'Income Statement'!E11 -> 0.27127727 | F9: ='Income Statement'!F15/'Income Statement'!F11 -> 0.25574939 | G9: ='Income Statement'!G15/'Income Statement'!G11 -> 0.26577133 | I9: =AVERAGE(C9:G9) -> 0.26338881 | J9: =AVERAGE(E9:G9) -> 0.26426599 | L9: 0.265 | M9: 0.268 | N9: 0.2585 | O9: 0.26 | P9: 0.2615
B10: Depreciation and Amortization | C10: ='Income Statement'!C18/'Income Statement'!C11 -> 0.20448588 | D10: ='Income Statement'!D18/'Income Statement'!D11 -> 0.17155748 | E10: ='Income Statement'!E18/'Income Statement'!E11 -> 0.16316607 | F10: ='Income Statement'!F18/'Income Statement'!F11 -> 0.15871007 | G10: ='Income Statement'!G18/'Income Statement'!G11 -> 0.15296289 | I10: =AVERAGE(C10:G10) -> 0.17017648 | J10: =AVERAGE(E10:G10) -> 0.15827968 | L10: 0.169 | M10: 0.161 | N10: 0.157 | O10: 0.156 | P10: 0.154
B11: Other (expense) income, net | C11: ='Income Statement'!C22/'Income Statement'!C11 -> -0.0024838363 | D11: ='Income Statement'!D22/'Income Statement'!D11 -> -0.00041472396 | E11: ='Income Statement'!E22/'Income Statement'!E11 -> 0.00086560248 | F11: ='Income Statement'!F22/'Income Statement'!F11 -> 0.0013882064 | G11: ='Income Statement'!G22/'Income Statement'!G11 -> -0.0025365478 | I11: =AVERAGE(C11:G11) -> -0.00063625985 | J11: =AVERAGE(E11:G11) -> -9.424631e-05 | L11: -0.0005 | M11: -0.0005 | N11: -0.0005 | O11: -0.0005 | P11: -0.0005
B12: Income Tax Expense | C12: ='Income Statement'!C24/'Income Statement'!C23 -> -0.097582811 | D12: ='Income Statement'!D24/'Income Statement'!D23 -> -0.17673236 | E12: ='Income Statement'!E24/'Income Statement'!E23 -> -0.24384035 | F12: ='Income Statement'!F24/'Income Statement'!F23 -> -0.22926862 | G12: ='Income Statement'!G24/'Income Statement'!G23 -> -0.230306 | I12: =AVERAGE(C12:G12) -> -0.19554603 | J12: =AVERAGE(E12:G12) -> -0.23447166 | L12: -0.11 | M12: -0.25 | N12: -0.225 | O12: -0.223 | P12: -0.23
B13: Balance Sheet:
B14: Cash and cash equivalents | C14: ='Balance Sheet'!C5/'Income Statement'!C11 -> 0.082765421 | D14: ='Balance Sheet'!D5/'Income Statement'!D11 -> 0.056641239 | E14: ='Balance Sheet'!E5/'Income Statement'!E11 -> 0.065365717 | F14: ='Balance Sheet'!F5/'Income Statement'!F11 -> 0.066449631 | G14: ='Balance Sheet'!G5/'Income Statement'!G11 -> 0.063391047 | I14: =AVERAGE(C14:G14) -> 0.066922611 | J14: =AVERAGE(E14,F14,G14) -> 0.065068799 | L14: 0.06 | M14: 0.058 | N14: 0.06 | O14: 0.062 | P14: 0.062
B15: Accounts receivable | C15: ='Balance Sheet'!C7/'Income Statement'!C11 -> 0.052347787 | D15: ='Balance Sheet'!D7/'Income Statement'!D11 -> 0.05586206 | E15: ='Balance Sheet'!E7/'Income Statement'!E11 -> 0.059726571 | F15: ='Balance Sheet'!F7/'Income Statement'!F11 -> 0.052530713 | G15: ='Balance Sheet'!G7/'Income Statement'!G11 -> 0.055192562 | I15: =AVERAGE(C15:G15) -> 0.055131939 | J15: =AVERAGE(E15,F15,G15) -> 0.055816615 | L15: 0.056 | M15: 0.057 | N15: 0.056 | O15: 0.055 | P15: 0.055
B16: Equipment installment plan receivables, | C16: ='Balance Sheet'!C8/'Income Statement'!C11 -> 0.059262588 | D16: ='Balance Sheet'!D8/'Income Statement'!D11 -> 0.064382753 | E16: ='Balance Sheet'!E8/'Income Statement'!E11 -> 0.056722422 | F16: ='Balance Sheet'!F8/'Income Statement'!F11 -> 0.053796069 | G16: ='Balance Sheet'!G8/'Income Statement'!G11 -> 0.056585399 | I16: =AVERAGE(C16:G16) -> 0.058149846 | J16: =AVERAGE(E16,F16,G16) -> 0.055701296 | L16: 0.058 | M16: 0.057 | N16: 0.054 | O16: 0.053 | P16: 0.054
B17: Inventory | C17: ='Balance Sheet'!C9/'Income Statement'!C19 -> 0.035055854 | D17: ='Balance Sheet'!D9/('Income Statement'!D13+'Income Statement'!D14) -> 0.052035574 | E17: ='Balance Sheet'!E9/('Income Statement'!E13+'Income Statement'!E14) -> 0.055585001 | F17: ='Balance Sheet'!F9/('Income Statement'!F13+'Income Statement'!F14) -> 0.054193505 | G17: ='Balance Sheet'!G9/('Income Statement'!G13+'Income Statement'!G14) -> 0.073381339 | I17: =AVERAGE(C17:G17) -> 0.054050255 | J17: =AVERAGE(E17,F17,G17) -> 0.061053281 | L17: 0.067 | M17: 0.064 | N17: 0.061 | O17: 0.06 | P17: 0.059
B18: Prepaid expenses | C18: ='Balance Sheet'!C10/'Income Statement'!C11 -> 0.0093112659 | D18: ='Balance Sheet'!D10/'Income Statement'!D11 -> 0.0084578552 | E18: ='Balance Sheet'!E10/'Income Statement'!E11 -> 0.0089360727 | F18: ='Balance Sheet'!F10/'Income Statement'!F11 -> 0.010810811 | G18: ='Balance Sheet'!G10/'Income Statement'!G11 -> 0.013758507 | I18: =AVERAGE(C18:G18) -> 0.010254902 | J18: =AVERAGE(E18,F18,G18) -> 0.011168464 | L18: 0.0125 | M18: 0.011 | N18: 0.01 | O18: 0.0095 | P18: 0.0095
B19: Other current assets | C19: ='Balance Sheet'!C21/'Income Statement'!C11 -> 0.040340498 | D19: ='Balance Sheet'!D21/'Income Statement'!D11 -> 0.051865629 | E19: ='Balance Sheet'!E21/'Income Statement'!E11 -> 0.053832837 | F19: ='Balance Sheet'!F21/'Income Statement'!F11 -> 0.053132678 | G19: ='Balance Sheet'!G21/'Income Statement'!G11 -> 0.11046439 | I19: =AVERAGE(C19:G19) -> 0.061927207 | J19: =AVERAGE(E19,F19,G19) -> 0.072476636 | L19: 0.08 | M19: 0.07 | N19: 0.063 | O19: 0.05 | P19: 0.048
B21: Property and equipment, net | C21: ='Balance Sheet'!C14/'Income Statement'!C11 -> 0.49680471 | D21: ='Balance Sheet'!D14/'Income Statement'!D11 -> 0.52891129 | E21: ='Balance Sheet'!E14/'Income Statement'!E11 -> 0.51467705 | F21: ='Balance Sheet'!F14/'Income Statement'!F11 -> 0.47337838 | G21: ='Balance Sheet'!G14/'Income Statement'!G11 -> 0.43407807 | I21: =AVERAGE(G21,F21,E21,D21,C21) -> 0.4895699 | J21: =AVERAGE(G21,F21,E21) -> 0.4740445 | L21: 0.41 | M21: 0.405 | N21: 0.405 | O21: 0.4 | P21: 0.4
B22: Operating lease right-of-use assets | C22: ='Balance Sheet'!C15/'Income Statement'!C11 -> 0.33649118 | D22: ='Balance Sheet'!D15/'Income Statement'!D11 -> 0.36087268 | E22: ='Balance Sheet'!E15/'Income Statement'!E11 -> 0.34541358 | F22: ='Balance Sheet'!F15/'Income Statement'!F11 -> 0.31201474 | G22: ='Balance Sheet'!G15/'Income Statement'!G11 -> 0.29093297 | I22: =AVERAGE(G22,F22,E22,D22,C22) -> 0.32914503 | J22: =AVERAGE(G22,F22,E22) -> 0.31612043 | L22: 0.285 | M22: 0.278 | N22: 0.274 | O22: 0.27 | P22: 0.27
B23: Financing lease right-of-use assets | C23: ='Balance Sheet'!C16/'Income Statement'!C11 -> 0.041463841 | D23: ='Balance Sheet'!D16/'Income Statement'!D11 -> 0.040931998 | E23: ='Balance Sheet'!E16/'Income Statement'!E11 -> 0.041625296 | F23: ='Balance Sheet'!F16/'Income Statement'!F11 -> 0.037972973 | G23: ='Balance Sheet'!G16/'Income Statement'!G11 -> 0.031253893 | I23: =AVERAGE(G23,F23,E23,D23,C23) -> 0.0386496 | J23: =AVERAGE(G23,F23,E23) -> 0.036950721 | L23: 0.0305 | M23: 0.03 | N23: 0.029 | O23: 0.028 | P23: 0.0275
B24: Goodwill | C24: ='Balance Sheet'!C17 -> 12188 | D24: ='Balance Sheet'!D17 -> 12234 | E24: ='Balance Sheet'!E17 -> 12234 | F24: ='Balance Sheet'!F17 -> 13005 | G24: ='Balance Sheet'!G17 -> 13678 | I24: =AVERAGE(G24,F24,E24,D24,C24) -> 12667.8 | J24: =AVERAGE(G24,F24,E24) -> 12972.333 | L24: =$G$24 -> 13678 | M24: =$G$24 -> 13678 | N24: =$G$24 -> 13678 | O24: =$G$24 -> 13678 | P24: =$G$24 -> 13678
B25: Spectrum licenses | C25: ='Balance Sheet'!C18 -> 92606 | D25: ='Balance Sheet'!D18 -> 95798 | E25: ='Balance Sheet'!E18 -> 96707 | F25: ='Balance Sheet'!F18 -> 100558 | G25: ='Balance Sheet'!G18 -> 98032 | I25: =AVERAGE(G25,F25,E25,D25,C25) -> 96740.2 | J25: =AVERAGE(G25,F25,E25) -> 98432.333 | L25: =$G$25 -> 98032 | M25: =$G$25 -> 98032 | N25: =$G$25 -> 98032 | O25: =$G$25 -> 98032 | P25: =$G$25 -> 98032
B26: Other intangible assets, net | C26: ='Balance Sheet'!C19/'Income Statement'!C11 -> 0.059075364 | D26: ='Balance Sheet'!D19/'Income Statement'!D11 -> 0.044086413 | E26: ='Balance Sheet'!E19/'Income Statement'!E11 -> 0.033325696 | F26: ='Balance Sheet'!F19/'Income Statement'!F11 -> 0.030859951 | G26: ='Balance Sheet'!G19/'Income Statement'!G11 -> 0.043517648 | I26: =AVERAGE(G26,F26,E26,D26,C26) -> 0.042173014 | J26: =AVERAGE(G26,F26,E26) -> 0.035901098 | L26: 0.04 | M26: 0.036 | N26: 0.032 | O26: 0.0305 | P26: 0.0305
B27: Equipment installment plan receivables | C27: ='Balance Sheet'!C20/'Income Statement'!C11 -> 0.035310417 | D27: ='Balance Sheet'!D20/'Income Statement'!D11 -> 0.031996582 | E27: ='Balance Sheet'!E20/'Income Statement'!E11 -> 0.025993533 | F27: ='Balance Sheet'!F20/'Income Statement'!F11 -> 0.027137592 | G27: ='Balance Sheet'!G20/'Income Statement'!G11 -> 0.030381954 | I27: =AVERAGE(G27,F27,E27,D27,C27) -> 0.030164016 | J27: =AVERAGE(G27,F27,E27) -> 0.027837693 | L27: 0.031 | M27: 0.0315 | N27: 0.031 | O27: 0.0305 | P27: 0.0305
B28: Other assets | C28: ='Balance Sheet'!C21/'Income Statement'!C11 -> 0.040340498 | D28: ='Balance Sheet'!D21/'Income Statement'!D11 -> 0.051865629 | E28: ='Balance Sheet'!E21/'Income Statement'!E11 -> 0.053832837 | F28: ='Balance Sheet'!F21/'Income Statement'!F11 -> 0.053132678 | G28: ='Balance Sheet'!G21/'Income Statement'!G11 -> 0.11046439 | I28: =AVERAGE(G28,F28,E28,D28,C28) -> 0.061927207 | J28: =AVERAGE(G28,F28,E28) -> 0.072476636 | L28: 0.08 | M28: 0.06 | N28: 0.055 | O28: 0.05 | P28: 0.048
B30: Accounts payable and accrued liabilities | C30: ='Balance Sheet'!C26/('Income Statement'!C13+'Income Statement'!C14) -> 0.31156946 | D30: ='Balance Sheet'!D26/('Income Statement'!D13+'Income Statement'!D14) -> 0.3390322 | E30: ='Balance Sheet'!E26/('Income Statement'!E13+'Income Statement'!E14) -> 0.34361336 | F30: ='Balance Sheet'!F26/('Income Statement'!F13+'Income Statement'!F14) -> 0.28540114 | G30: ='Balance Sheet'!G26/('Income Statement'!G13+'Income Statement'!G14) -> 0.31366327 | I30: =AVERAGE(C30:G30) -> 0.31865589 | J30: =AVERAGE(E30:G30) -> 0.31422592 | L30: 0.303 | M30: 0.272 | N30: 0.296 | O30: 0.308 | P30: 0.312
B31: Deferred revenue | C31: ='Balance Sheet'!C29/'Income Statement'!C11 -> 0.010684241 | D31: ='Balance Sheet'!D29/'Income Statement'!D11 -> 0.0098025663 | E31: ='Balance Sheet'!E29/'Income Statement'!E11 -> 0.010501795 | F31: ='Balance Sheet'!F29/'Income Statement'!F11 -> 0.015012285 | G31: ='Balance Sheet'!G29/'Income Statement'!G11 -> 0.017359499 | I31: =AVERAGE(C31:G31) -> 0.012672077 | J31: =AVERAGE(E31:G31) -> 0.014291193 | L31: 0.0193 | M31: 0.0246 | N31: 0.0261 | O31: 0.0283 | P31: 0.0301
B32: Short-term operating lease liabilities | C32: ='Balance Sheet'!C30/'Income Statement'!C11 -> 0.042749445 | D32: ='Balance Sheet'!D30/'Income Statement'!D11 -> 0.044136683 | E32: ='Balance Sheet'!E30/'Income Statement'!E11 -> 0.045253189 | F32: ='Balance Sheet'!F30/'Income Statement'!F11 -> 0.040307125 | G32: ='Balance Sheet'!G30/'Income Statement'!G11 -> 0.043189256 | I32: =AVERAGE(C32:G32) -> 0.043127139 | J32: =AVERAGE(E32:G32) -> 0.042916523 | L32: 0.0445 | M32: 0.0425 | N32: 0.0419 | O32: 0.0428 | P32: 0.0432
B33: Short-term financing lease liabilities | C33: ='Balance Sheet'!C31/'Income Statement'!C11 -> 0.01397938 | D33: ='Balance Sheet'!D31/'Income Statement'!D11 -> 0.014590743 | E33: ='Balance Sheet'!E31/'Income Statement'!E11 -> 0.016039105 | F33: ='Balance Sheet'!F31/'Income Statement'!F11 -> 0.014434889 | G33: ='Balance Sheet'!G31/'Income Statement'!G11 -> 0.013169666 | I33: =AVERAGE(C33:G33) -> 0.014442757 | J33: =AVERAGE(E33:G33) -> 0.014547887 | L33: 0.0141 | M33: 0.0152 | N33: 0.0158 | O33: 0.0147 | P33: 0.0139
B34: Other current liabilities | C34: ='Balance Sheet'!C32/'Income Statement'!C11 -> 0.013355301 | D34: ='Balance Sheet'!D32/'Income Statement'!D11 -> 0.023249676 | E34: ='Balance Sheet'!E32/'Income Statement'!E11 -> 0.016497365 | F34: ='Balance Sheet'!F32/'Income Statement'!F11 -> 0.024140049 | G34: ='Balance Sheet'!G32/'Income Statement'!G11 -> 0.029158976 | I34: =AVERAGE(C34:G34) -> 0.021280273 | J34: =AVERAGE(E34:G34) -> 0.023265463 | L34: 0.0305 | M34: 0.0321 | N34: 0.0315 | O34: 0.0329 | P34: 0.0333
